Workbook

Sheet Food Database
A1: All Nutrition Facts Are For 100-g / 100-ml Serving | G1: Notes
A2: Food | B2: Carbs (g) | C2: Protein (g) | D2: Fats (g) | E2: Calories | G2: My red mug at home: 200 ml
A3: Bread (Baladi or Shami) | B3: 55 | C3: 9 | D3: 2 | E3: =(B3+C3)*4+D3*9 -> 274 | G3: Rice and pasta weight gets doubled after being cooked
A4: Egyptian Roumy Cheese | B4: 1 | C4: 25 | D4: 30 | E4: =(B4+C4)*4+D4*9 -> 374 | G4: Average weight of a date: 12 gm
A5: Boiled Eggs | B5: 1.1 | C5: 13 | D5: 11 | E5: =(B5+C5)*4+D5*9 -> 155.4 | G5: Mum puts two tablespoons of tomato sauce on 785 grams of cooked pasta, which weigh around 66 grams of tomato sauce. This means the amount of tomato sauce per 100 grams of cooked pasta is ~8.4 grams.
A6: Banana Milk | B6: =(23/2) -> 11.5 | C6: 3 | D6: 1.5 | E6: =(B6+C6)*4+D6*9 -> 71.5 | G6: Average weight of an organic banana: 120 gm
A7: Kayy Oats | B7: 60.4 | C7: 30 | D7: 2 | E7: =(B7+C7)*4+D7*9 -> 379.6 | G7: Average weight of a cucumber: 90 gm
A8: Lamar Skimmed Milk | B8: 5.2 | C8: 3.3 | D8: 0.1 | E8: =(B8+C8)*4+D8*9 -> 34.9 | G8: Average weight of an egg: 45 gm
A9: Honey | B9: 82.4 | C9: 0.3 | D9: 0 | E9: =(B9+C9)*4+D9*9 -> 330.8 | G9: Average weight of a walnut: 2.5 gm
A10: Uncooked Rice (Al Doha) | B10: 81.2 | C10: 6.8 | D10: 0.9 | E10: =(B10+C10)*4+D10*9 -> 360.1 | G10: 1 tbsp of seuodi extra virgin olive oil is 15 ml
A11: Skinless, Boneless, Cooked Chicken Breasts | B11: 0 | C11: 31 | D11: 3.6 | E11: =(B11+C11)*4+D11*9 -> 156.4
A12: Suntop Orange Juice | B12: 14 | C12: 0 | D12: 0 | E12: =(B12+C12)*4+D12*9 -> 56
A13: Rich Bake Normal Toast (Blue) | B13: 53 | C13: 11 | D13: 4 | E13: =(B13+C13)*4+D13*9 -> 292
A14: Avante Cottage Cheese | B14: 2.7 | C14: 12.5 | D14: 4.5 | E14: =(B14+C14)*4+D14*9 -> 101.3
A15: Zero Protein Bar | B15: =(25/60*100) -> 41.666667 | C15: =(24*100/60) -> 40 | D15: =(3*100/60) -> 5 | E15: =(B15+C15)*4+D15*9 -> 371.66667
A16: Kayy Protein Puffs | B16: =(40*100/60) -> 66.666667 | C16: =(10*100/60) -> 16.666667 | D16: =(10*100/60) -> 16.666667 | E16: =(B16+C16)*4+D16*9 -> 483.33333
A17: Bananas | B17: 23 | C17: 1.1 | D17: 0.3 | E17: =(B17+C17)*4+D17*9 -> 99.1
A18: Dates | B18: 75 | C18: 1.8 | D18: 0.2 | E18: =(B18+C18)*4+D18*9 -> 309
A19: Walnuts | B19: 13.7 | C19: 15.2 | D19: 65.2 | E19: =(B19+C19)*4+D19*9 -> 702.4
A20: Hazelnuts | B20: 16.7 | C20: 14.1 | D20: 60.8 | E20: =(B20+C20)*4+D20*9 -> 670.4
A21: Peanuts | B21: 16.1 | C21: 25.8 | D21: 49.2 | E21: =(B21+C21)*4+D21*9 -> 610.4
A22: Cucumber (With Skin) | B22: 3.6 | C22: 0.7 | D22: 0.1 | E22: =(B22+C22)*4+D22*9 -> 18.1
A23: Nutty Peanut Butter | B23: =(7*100/32) -> 21.875 | C23: =(8*100/32) -> 25 | D23: =(16*100/32) -> 50 | E23: =(B23+C23)*4+D23*9 -> 637.5
A24: Harvest Beans | B24: =(23*100/130) -> 17.692308 | C24: =(7*100/130) -> 5.3846154 | D24: 0 | E24: =(B24+C24)*4+D24*9 -> 92.307692
A25: Uncooked Basmaty Rice (Mexicana) | B25: =(35*100/164) -> 21.341463 | C25: =(7*100/164) -> 4.2682927 | D25: =(1*100/164) -> 0.6097561 | E25: =(B25+C25)*4+D25*9 -> 107.92683
A26: Uncooked Pasta (Regina) | B26: 73 | C26: 12.5 | D26: 0.75 | E26: =(B26+C26)*4+D26*9 -> 348.75
A27: Chicken Spices (Bab Elsham) | B27: 36.81 | C27: 16.75 | D27: 5.76 | E27: =(B27+C27)*4+D27*9 -> 266.08
A28: Cooked Rice (Al Doha) | B28: =(B10/2) -> 40.6 | C28: =(C10/2) -> 3.4 | D28: =(D10/2) -> 0.45 | E28: =(B28+C28)*4+D28*9 -> 180.05
A29: Juhayna Full Cream Yogurt (105 gm) | B29: =(5.3*100/105) -> 5.047619 | C29: =(3.8*100/105) -> 3.6190476 | D29: =(3.4*100/105) -> 3.2380952 | E29: =(B29+C29)*4+D29*9 -> 63.809524
A30: Juhayna Low-Fat Yogurt (105 gm) | B30: =(5.3*100/105) -> 5.047619 | C30: =(3.4*100/105) -> 3.2380952 | D30: =(1.6*100/105) -> 1.5238095 | E30: =(B30+C30)*4+D30*9 -> 46.857143
A31: Juhayna Low-Fat Greek Yogurt (180 gm) | B31: =(6.5*100/180) -> 3.6111111 | C31: =(15*100/180) -> 8.3333333 | D31: =(0.36*100/180) -> 0.2 | E31: =(B31+C31)*4+D31*9 -> 49.577778
A32: Juhayna Full-Cream Greek Yogurt (180 gm) | B32: =(7.2*100/180) -> 4 | C32: =(15*100/180) -> 8.3333333 | D32: =(9*100/180) -> 5 | E32: =(B32+C32)*4+D32*9 -> 94.333333
A33: Yopolis Greek Double Zero Yogurt (150 gm) | B33: =(13.3*100/150) -> 8.8666667 | C33: =(11*100/150) -> 7.3333333 | D33: 0 | E33: =(B33+C33)*4+D33*9 -> 64.8
A34: Almarai Full-Cream Greek Yogurt (170 gm) | B34: =(11.7*100/170) -> 6.8823529 | C34: =(10.2*100/170) -> 6 | D34: =(8.5*100/170) -> 5 | E34: =(B34+C34)*4+D34*9 -> 96.529412
A35: Almarai Low-Fat Greek Yogurt (170 gm) | B35: =(10.54*100/170) -> 6.2 | C35: =(10.54*100/170) -> 6.2 | D35: =(0.34*100/170) -> 0.2 | E35: =(B35+C35)*4+D35*9 -> 51.4
A36: Tomato Sauce | B36: =(13*100/33) -> 39.393939 | C36: =(3.2*100/33) -> 9.6969697 | D36: =(0.5*100/33) -> 1.5151515 | E36: =(B36+C36)*4+D36*9 -> 210
A37: Cooked Pasta (Regina) | B37: =(B26/2) -> 36.5 | C37: =(C26/2) -> 6.25 | D37: =(D26/2) -> 0.375 | E37: =(B37+C37)*4+D37*9 -> 174.375
A38: Fresh Orange Juice (without any additives) | B38: 10.4 | C38: 0.7 | D38: 0.2 | E38: =(B38+C38)*4+D38*9 -> 46.2
A39: Riefy Skimmed Milk | B39: =(9.6/2) -> 4.8 | C39: =(6.6/2) -> 3.3 | D39: =(0.5/2) -> 0.25 | E39: =(B39+C39)*4+D39*9 -> 34.65
A40: Kayy Protein Bites | B40: =(36/60*100) -> 60 | C40: =(11/60*100) -> 18.333333 | D40: =(8/60*100) -> 13.333333 | E40: =(B40+C40)*4+D40*9 -> 433.33333
...

Sheet Meal Tracker (Army)
A1: Food | B1: Weight (g) / Volume (ml) | C1: Carbs (g) | D1: Protein (g) | E1: Fats (g) | F1: Calories
A2: Bread (Baladi or Shami) | B2: 112.5 | C2: =IFERROR((VLOOKUP(A2,'Food Database'!$A$2:$E$105,2,FALSE) * B2) / 100, "") -> 61.875 | D2: =IFERROR((VLOOKUP(A2,'Food Database'!$A$2:$E$105,3,FALSE) * B2) / 100, "") -> 10.125 | E2: =IFERROR((VLOOKUP(A2,'Food Database'!$A$2:$E$105,4,FALSE) * B2) / 100, "") -> 2.25 | F2: =IFERROR((VLOOKUP(A2,'Food Database'!$A$2:$E$105,5,FALSE) * B2) / 100, "") -> 308.25
A3: Boiled Eggs | B3: 135 | C3: =IFERROR((VLOOKUP(A3,'Food Database'!$A$2:$E$105,2,FALSE) * B3) / 100, "") -> 1.485 | D3: =IFERROR((VLOOKUP(A3,'Food Database'!$A$2:$E$105,3,FALSE) * B3) / 100, "") -> 17.55 | E3: =IFERROR((VLOOKUP(A3,'Food Database'!$A$2:$E$105,4,FALSE) * B3) / 100, "") -> 14.85 | F3: =IFERROR((VLOOKUP(A3,'Food Database'!$A$2:$E$105,5,FALSE) * B3) / 100, "") -> 209.79
A4: Kayy Protein Puffs | B4: 60 | C4: =IFERROR((VLOOKUP(A4,'Food Database'!$A$2:$E$105,2,FALSE) * B4) / 100, "") -> 40 | D4: =IFERROR((VLOOKUP(A4,'Food Database'!$A$2:$E$105,3,FALSE) * B4) / 100, "") -> 10 | E4: =IFERROR((VLOOKUP(A4,'Food Database'!$A$2:$E$105,4,FALSE) * B4) / 100, "") -> 10 | F4: =IFERROR((VLOOKUP(A4,'Food Database'!$A$2:$E$105,5,FALSE) * B4) / 100, "") -> 290
A5: Cooked Rice (Al Doha) | B5: 250 | C5: =IFERROR((VLOOKUP(A5,'Food Database'!$A$2:$E$105,2,FALSE) * B5) / 100, "") -> 101.5 | D5: =IFERROR((VLOOKUP(A5,'Food Database'!$A$2:$E$105,3,FALSE) * B5) / 100, "") -> 8.5 | E5: =IFERROR((VLOOKUP(A5,'Food Database'!$A$2:$E$105,4,FALSE) * B5) / 100, "") -> 1.125 | F5: =IFERROR((VLOOKUP(A5,'Food Database'!$A$2:$E$105,5,FALSE) * B5) / 100, "") -> 450.125
A6: Skinless, Boneless, Cooked Chicken Breasts | B6: 200 | C6: =IFERROR((VLOOKUP(A6,'Food Database'!$A$2:$E$105,2,FALSE) * B6) / 100, "") -> 0 | D6: =IFERROR((VLOOKUP(A6,'Food Database'!$A$2:$E$105,3,FALSE) * B6) / 100, "") -> 62 | E6: =IFERROR((VLOOKUP(A6,'Food Database'!$A$2:$E$105,4,FALSE) * B6) / 100, "") -> 7.2 | F6: =IFERROR((VLOOKUP(A6,'Food Database'!$A$2:$E$105,5,FALSE) * B6) / 100, "") -> 312.8 | J6: Total Macro-Nutrients
A7: Suntop Orange Juice | B7: 250 | C7: =IFERROR((VLOOKUP(A7,'Food Database'!$A$2:$E$105,2,FALSE) * B7) / 100, "") -> 35 | D7: =IFERROR((VLOOKUP(A7,'Food Database'!$A$2:$E$105,3,FALSE) * B7) / 100, "") -> 0 | E7: =IFERROR((VLOOKUP(A7,'Food Database'!$A$2:$E$105,4,FALSE) * B7) / 100, "") -> 0 | F7: =IFERROR((VLOOKUP(A7,'Food Database'!$A$2:$E$105,5,FALSE) * B7) / 100, "") -> 140 | J7: - | K7: Carbs | L7: Protein | M7: Fats | N7: Calories
A8: Kayy Oats | B8: 100 | C8: =IFERROR((VLOOKUP(A8,'Food Database'!$A$2:$E$105,2,FALSE) * B8) / 100, "") -> 60.4 | D8: =IFERROR((VLOOKUP(A8,'Food Database'!$A$2:$E$105,3,FALSE) * B8) / 100, "") -> 30 | E8: =IFERROR((VLOOKUP(A8,'Food Database'!$A$2:$E$105,4,FALSE) * B8) / 100, "") -> 2 | F8: =IFERROR((VLOOKUP(A8,'Food Database'!$A$2:$E$105,5,FALSE) * B8) / 100, "") -> 379.6 | J8: Amount (g) | K8: =SUM(C2:C71) -> 423.688 | L8: =SUM(D2:D71) -> 177.726 | M8: =SUM(E2:E71) -> 67.445 | N8: =SUM(F2:F71) -> 3012.661
A9: Honey | B9: 21 | C9: =IFERROR((VLOOKUP(A9,'Food Database'!$A$2:$E$105,2,FALSE) * B9) / 100, "") -> 17.304 | D9: =IFERROR((VLOOKUP(A9,'Food Database'!$A$2:$E$105,3,FALSE) * B9) / 100, "") -> 0.063 | E9: =IFERROR((VLOOKUP(A9,'Food Database'!$A$2:$E$105,4,FALSE) * B9) / 100, "") -> 0 | F9: =IFERROR((VLOOKUP(A9,'Food Database'!$A$2:$E$105,5,FALSE) * B9) / 100, "") -> 69.468 | J9: Percentage | K9: =(K8*4)/N8 -> 0.56254321 | L9: =(L8*4)/N8 -> 0.23597212 | M9: =(M8*9)/N8 -> 0.20148467 | N9: -
A10: Rich Bake Normal Toast (Blue) | B10: 80 | C10: =IFERROR((VLOOKUP(A10,'Food Database'!$A$2:$E$105,2,FALSE) * B10) / 100, "") -> 42.4 | D10: =IFERROR((VLOOKUP(A10,'Food Database'!$A$2:$E$105,3,FALSE) * B10) / 100, "") -> 8.8 | E10: =IFERROR((VLOOKUP(A10,'Food Database'!$A$2:$E$105,4,FALSE) * B10) / 100, "") -> 3.2 | F10: =IFERROR((VLOOKUP(A10,'Food Database'!$A$2:$E$105,5,FALSE) * B10) / 100, "") -> 233.6
A11: Avante Cottage Cheese | B11: 100 | C11: =IFERROR((VLOOKUP(A11,'Food Database'!$A$2:$E$105,2,FALSE) * B11) / 100, "") -> 2.7 | D11: =IFERROR((VLOOKUP(A11,'Food Database'!$A$2:$E$105,3,FALSE) * B11) / 100, "") -> 12.5 | E11: =IFERROR((VLOOKUP(A11,'Food Database'!$A$2:$E$105,4,FALSE) * B11) / 100, "") -> 4.5 | F11: =IFERROR((VLOOKUP(A11,'Food Database'!$A$2:$E$105,5,FALSE) * B11) / 100, "") -> 101.3
A12: Egyptian Roumy Cheese | B12: 38 | C12: =IFERROR((VLOOKUP(A12,'Food Database'!$A$2:$E$105,2,FALSE) * B12) / 100, "") -> 0.38 | D12: =IFERROR((VLOOKUP(A12,'Food Database'!$A$2:$E$105,3,FALSE) * B12) / 100, "") -> 9.5 | E12: =IFERROR((VLOOKUP(A12,'Food Database'!$A$2:$E$105,4,FALSE) * B12) / 100, "") -> 11.4 | F12: =IFERROR((VLOOKUP(A12,'Food Database'!$A$2:$E$105,5,FALSE) * B12) / 100, "") -> 142.12
A13: Banana Milk | B13: 200 | C13: =IFERROR((VLOOKUP(A13,'Food Database'!$A$2:$E$105,2,FALSE) * B13) / 100, "") -> 23 | D13: =IFERROR((VLOOKUP(A13,'Food Database'!$A$2:$E$105,3,FALSE) * B13) / 100, "") -> 6 | E13: =IFERROR((VLOOKUP(A13,'Food Database'!$A$2:$E$105,4,FALSE) * B13) / 100, "") -> 3 | F13: =IFERROR((VLOOKUP(A13,'Food Database'!$A$2:$E$105,5,FALSE) * B13) / 100, "") -> 143
A14: Dates | B14: 48 | C14: =IFERROR((VLOOKUP(A14,'Food Database'!$A$2:$E$105,2,FALSE) * B14) / 100, "") -> 36 | D14: =IFERROR((VLOOKUP(A14,'Food Database'!$A$2:$E$105,3,FALSE) * B14) / 100, "") -> 0.864 | E14: =IFERROR((VLOOKUP(A14,'Food Database'!$A$2:$E$105,4,FALSE) * B14) / 100, "") -> 0.096 | F14: =IFERROR((VLOOKUP(A14,'Food Database'!$A$2:$E$105,5,FALSE) * B14) / 100, "") -> 148.32
A15: Walnuts | B15: 12 | C15: =IFERROR((VLOOKUP(A15,'Food Database'!$A$2:$E$105,2,FALSE) * B15) / 100, "") -> 1.644 | D15: =IFERROR((VLOOKUP(A15,'Food Database'!$A$2:$E$105,3,FALSE) * B15) / 100, "") -> 1.824 | E15: =IFERROR((VLOOKUP(A15,'Food Database'!$A$2:$E$105,4,FALSE) * B15) / 100, "") -> 7.824 | F15: =IFERROR((VLOOKUP(A15,'Food Database'!$A$2:$E$105,5,FALSE) * B15) / 100, "") -> 84.288
C16: =IFERROR((VLOOKUP(A16,'Food Database'!$A$2:$E$105,2,FALSE) * B16) / 100, "") | D16: =IFERROR((VLOOKUP(A16,'Food Database'!$A$2:$E$105,3,FALSE) * B16) / 100, "") | E16: =IFERROR((VLOOKUP(A16,'Food Database'!$A$2:$E$105,4,FALSE) * B16) / 100, "") | F16: =IFERROR((VLOOKUP(A16,'Food Database'!$A$2:$E$105,5,FALSE) * B16) / 100, "")
C17: =IFERROR((VLOOKUP(A17,'Food Database'!$A$2:$E$105,2,FALSE) * B17) / 100, "") | D17: =IFERROR((VLOOKUP(A17,'Food Database'!$A$2:$E$105,3,FALSE) * B17) / 100, "") | E17: =IFERROR((VLOOKUP(A17,'Food Database'!$A$2:$E$105,4,FALSE) * B17) / 100, "") | F17: =IFERROR((VLOOKUP(A17,'Food Database'!$A$2:$E$105,5,FALSE) * B17) / 100, "")
C18: =IFERROR((VLOOKUP(A18,'Food Database'!$A$2:$E$105,2,FALSE) * B18) / 100, "") | D18: =IFERROR((VLOOKUP(A18,'Food Database'!$A$2:$E$105,3,FALSE) * B18) / 100, "") | E18: =IFERROR((VLOOKUP(A18,'Food Database'!$A$2:$E$105,4,FALSE) * B18) / 100, "") | F18: =IFERROR((VLOOKUP(A18,'Food Database'!$A$2:$E$105,5,FALSE) * B18) / 100, "")
C19: =IFERROR((VLOOKUP(A19,'Food Database'!$A$2:$E$105,2,FALSE) * B19) / 100, "") | D19: =IFERROR((VLOOKUP(A19,'Food Database'!$A$2:$E$105,3,FALSE) * B19) / 100, "") | E19: =IFERROR((VLOOKUP(A19,'Food Database'!$A$2:$E$105,4,FALSE) * B19) / 100, "") | F19: =IFERROR((VLOOKUP(A19,'Food Database'!$A$2:$E$105,5,FALSE) * B19) / 100, "")
C20: =IFERROR((VLOOKUP(A20,'Food Database'!$A$2:$E$105,2,FALSE) * B20) / 100, "") | D20: =IFERROR((VLOOKUP(A20,'Food Database'!$A$2:$E$105,3,FALSE) * B20) / 100, "") | E20: =IFERROR((VLOOKUP(A20,'Food Database'!$A$2:$E$105,4,FALSE) * B20) / 100, "") | F20: =IFERROR((VLOOKUP(A20,'Food Database'!$A$2:$E$105,5,FALSE) * B20) / 100, "")
C21: =IFERROR((VLOOKUP(A21,'Food Database'!$A$2:$E$105,2,FALSE) * B21) / 100, "") | D21: =IFERROR((VLOOKUP(A21,'Food Database'!$A$2:$E$105,3,FALSE) * B21) / 100, "") | E21: =IFERROR((VLOOKUP(A21,'Food Database'!$A$2:$E$105,4,FALSE) * B21) / 100, "") | F21: =IFERROR((VLOOKUP(A21,'Food Database'!$A$2:$E$105,5,FALSE) * B21) / 100, "")
C22: =IFERROR((VLOOKUP(A22,'Food Database'!$A$2:$E$105,2,FALSE) * B22) / 100, "") | D22: =IFERROR((VLOOKUP(A22,'Food Database'!$A$2:$E$105,3,FALSE) * B22) / 100, "") | E22: =IFERROR((VLOOKUP(A22,'Food Database'!$A$2:$E$105,4,FALSE) * B22) / 100, "") | F22: =IFERROR((VLOOKUP(A22,'Food Database'!$A$2:$E$105,5,FALSE) * B22) / 100, "")
C23: =IFERROR((VLOOKUP(A23,'Food Database'!$A$2:$E$105,2,FALSE) * B23) / 100, "") | D23: =IFERROR((VLOOKUP(A23,'Food Database'!$A$2:$E$105,3,FALSE) * B23) / 100, "") | E23: =IFERROR((VLOOKUP(A23,'Food Database'!$A$2:$E$105,4,FALSE) * B23) / 100, "") | F23: =IFERROR((VLOOKUP(A23,'Food Database'!$A$2:$E$105,5,FALSE) * B23) / 100, "")
C24: =IFERROR((VLOOKUP(A24,'Food Database'!$A$2:$E$105,2,FALSE) * B24) / 100, "") | D24: =IFERROR((VLOOKUP(A24,'Food Database'!$A$2:$E$105,3,FALSE) * B24) / 100, "") | E24: =IFERROR((VLOOKUP(A24,'Food Database'!$A$2:$E$105,4,FALSE) * B24) / 100, "") | F24: =IFERROR((VLOOKUP(A24,'Food Database'!$A$2:$E$105,5,FALSE) * B24) / 100, "")
C25: =IFERROR((VLOOKUP(A25,'Food Database'!$A$2:$E$105,2,FALSE) * B25) / 100, "") | D25: =IFERROR((VLOOKUP(A25,'Food Database'!$A$2:$E$105,3,FALSE) * B25) / 100, "") | E25: =IFERROR((VLOOKUP(A25,'Food Database'!$A$2:$E$105,4,FALSE) * B25) / 100, "") | F25: =IFERROR((VLOOKUP(A25,'Food Database'!$A$2:$E$105,5,FALSE) * B25) / 100, "")
C26: =IFERROR((VLOOKUP(A26,'Food Database'!$A$2:$E$105,2,FALSE) * B26) / 100, "") | D26: =IFERROR((VLOOKUP(A26,'Food Database'!$A$2:$E$105,3,FALSE) * B26) / 100, "") | E26: =IFERROR((VLOOKUP(A26,'Food Database'!$A$2:$E$105,4,FALSE) * B26) / 100, "") | F26: =IFERROR((VLOOKUP(A26,'Food Database'!$A$2:$E$105,5,FALSE) * B26) / 100, "")
C27: =IFERROR((VLOOKUP(A27,'Food Database'!$A$2:$E$105,2,FALSE) * B27) / 100, "") | D27: =IFERROR((VLOOKUP(A27,'Food Database'!$A$2:$E$105,3,FALSE) * B27) / 100, "") | E27: =IFERROR((VLOOKUP(A27,'Food Database'!$A$2:$E$105,4,FALSE) * B27) / 100, "") | F27: =IFERROR((VLOOKUP(A27,'Food Database'!$A$2:$E$105,5,FALSE) * B27) / 100, "")
... C72: =IFERROR((VLOOKUP(A72,'Food Database'!$A$2:$E$105,2,FALSE) * B72) / 100, "") | D72: =IFERROR((VLOOKUP(A72,'Food Database'!$A$2:$E$105,3,FALSE) * B72) / 100, "") | E72: =IFERROR((VLOOKUP(A72,'Food Database'!$A$2:$E$105,4,FALSE) * B72) / 100, "") | F72: =IFERROR((VLOOKUP(A72,'Food Database'!$A$2:$E$105,5,FALSE) * B72) / 100, "")

Sheet Meal Tracker (Normal)
A1: Food | B1: Weight (g) / Volume (ml) | C1: Carbs (g) | D1: Protein (g) | E1: Fats (g) | F1: Calories
A2: Bread (Baladi or Shami) | B2: 75 | C2: =IFERROR((VLOOKUP(A2,'Food Database'!$A$2:$E$105,2,FALSE) * B2) / 100, "") -> 41.25 | D2: =IFERROR((VLOOKUP(A2,'Food Database'!$A$2:$E$105,3,FALSE) * B2) / 100, "") -> 6.75 | E2: =IFERROR((VLOOKUP(A2,'Food Database'!$A$2:$E$105,4,FALSE) * B2) / 100, "") -> 1.5 | F2: =IFERROR((VLOOKUP(A2,'Food Database'!$A$2:$E$105,5,FALSE) * B2) / 100, "") -> 205.5
A3: Egyptian Roumy Cheese | B3: 70 | C3: =IFERROR((VLOOKUP(A3,'Food Database'!$A$2:$E$105,2,FALSE) * B3) / 100, "") -> 0.7 | D3: =IFERROR((VLOOKUP(A3,'Food Database'!$A$2:$E$105,3,FALSE) * B3) / 100, "") -> 17.5 | E3: =IFERROR((VLOOKUP(A3,'Food Database'!$A$2:$E$105,4,FALSE) * B3) / 100, "") -> 21 | F3: =IFERROR((VLOOKUP(A3,'Food Database'!$A$2:$E$105,5,FALSE) * B3) / 100, "") -> 261.8
A4: Boiled Eggs | B4: 90 | C4: =IFERROR((VLOOKUP(A4,'Food Database'!$A$2:$E$105,2,FALSE) * B4) / 100, "") -> 0.99 | D4: =IFERROR((VLOOKUP(A4,'Food Database'!$A$2:$E$105,3,FALSE) * B4) / 100, "") -> 11.7 | E4: =IFERROR((VLOOKUP(A4,'Food Database'!$A$2:$E$105,4,FALSE) * B4) / 100, "") -> 9.9 | F4: =IFERROR((VLOOKUP(A4,'Food Database'!$A$2:$E$105,5,FALSE) * B4) / 100, "") -> 139.86
A5: Bell Pepper | B5: 80 | C5: =IFERROR((VLOOKUP(A5,'Food Database'!$A$2:$E$105,2,FALSE) * B5) / 100, "") -> 4.8 | D5: =IFERROR((VLOOKUP(A5,'Food Database'!$A$2:$E$105,3,FALSE) * B5) / 100, "") -> 0.8 | E5: =IFERROR((VLOOKUP(A5,'Food Database'!$A$2:$E$105,4,FALSE) * B5) / 100, "") -> 0.24 | F5: =IFERROR((VLOOKUP(A5,'Food Database'!$A$2:$E$105,5,FALSE) * B5) / 100, "") -> 24.56
A6: Carrots | B6: 85 | C6: =IFERROR((VLOOKUP(A6,'Food Database'!$A$2:$E$105,2,FALSE) * B6) / 100, "") -> 8.5 | D6: =IFERROR((VLOOKUP(A6,'Food Database'!$A$2:$E$105,3,FALSE) * B6) / 100, "") -> 0.765 | E6: =IFERROR((VLOOKUP(A6,'Food Database'!$A$2:$E$105,4,FALSE) * B6) / 100, "") -> 0.17 | F6: =IFERROR((VLOOKUP(A6,'Food Database'!$A$2:$E$105,5,FALSE) * B6) / 100, "") -> 38.59
A7: Banana Milk | B7: 200 | C7: =IFERROR((VLOOKUP(A7,'Food Database'!$A$2:$E$105,2,FALSE) * B7) / 100, "") -> 23 | D7: =IFERROR((VLOOKUP(A7,'Food Database'!$A$2:$E$105,3,FALSE) * B7) / 100, "") -> 6 | E7: =IFERROR((VLOOKUP(A7,'Food Database'!$A$2:$E$105,4,FALSE) * B7) / 100, "") -> 3 | F7: =IFERROR((VLOOKUP(A7,'Food Database'!$A$2:$E$105,5,FALSE) * B7) / 100, "") -> 143
A8: Kayy Oats | B8: 100 | C8: =IFERROR((VLOOKUP(A8,'Food Database'!$A$2:$E$105,2,FALSE) * B8) / 100, "") -> 60.4 | D8: =IFERROR((VLOOKUP(A8,'Food Database'!$A$2:$E$105,3,FALSE) * B8) / 100, "") -> 30 | E8: =IFERROR((VLOOKUP(A8,'Food Database'!$A$2:$E$105,4,FALSE) * B8) / 100, "") -> 2 | F8: =IFERROR((VLOOKUP(A8,'Food Database'!$A$2:$E$105,5,FALSE) * B8) / 100, "") -> 379.6 | J8: Total Macro-Nutrients
A9: Lamar Full-Cream Milk | B9: 165 | C9: =IFERROR((VLOOKUP(A9,'Food Database'!$A$2:$E$105,2,FALSE) * B9) / 100, "") -> 7.92 | D9: =IFERROR((VLOOKUP(A9,'Food Database'!$A$2:$E$105,3,FALSE) * B9) / 100, "") -> 5.445 | E9: =IFERROR((VLOOKUP(A9,'Food Database'!$A$2:$E$105,4,FALSE) * B9) / 100, "") -> 4.95 | F9: =IFERROR((VLOOKUP(A9,'Food Database'!$A$2:$E$105,5,FALSE) * B9) / 100, "") -> 98.01 | J9: - | K9: Carbs | L9: Protein | M9: Fats | N9: Calories
A10: Honey | B10: 8 | C10: =IFERROR((VLOOKUP(A10,'Food Database'!$A$2:$E$105,2,FALSE) * B10) / 100, "") -> 6.592 | D10: =IFERROR((VLOOKUP(A10,'Food Database'!$A$2:$E$105,3,FALSE) * B10) / 100, "") -> 0.024 | E10: =IFERROR((VLOOKUP(A10,'Food Database'!$A$2:$E$105,4,FALSE) * B10) / 100, "") -> 0 | F10: =IFERROR((VLOOKUP(A10,'Food Database'!$A$2:$E$105,5,FALSE) * B10) / 100, "") -> 26.464 | J10: Amount (g) | K10: =SUM(C2:C70) -> 247.717 | L10: =SUM(D2:D70) -> 175.699 | M10: =SUM(E2:E70) -> 82.242692 | N10: =SUM(F2:F70) -> 2433.8482
A11: Walnuts | B11: =2.5*8 -> 20 | C11: =IFERROR((VLOOKUP(A11,'Food Database'!$A$2:$E$105,2,FALSE) * B11) / 100, "") -> 2.74 | D11: =IFERROR((VLOOKUP(A11,'Food Database'!$A$2:$E$105,3,FALSE) * B11) / 100, "") -> 3.04 | E11: =IFERROR((VLOOKUP(A11,'Food Database'!$A$2:$E$105,4,FALSE) * B11) / 100, "") -> 13.04 | F11: =IFERROR((VLOOKUP(A11,'Food Database'!$A$2:$E$105,5,FALSE) * B11) / 100, "") -> 140.48 | J11: Percentage | K11: =(K10*4)/N10 -> 0.40711988 | L11: =(L10*4)/N10 -> 0.28875917 | M11: =(M10*9)/N10 -> 0.30412095 | N11: -
A12: Juhayna Low-Fat Greek Yogurt (180 gm) | B12: 180 | C12: =IFERROR((VLOOKUP(A12,'Food Database'!$A$2:$E$105,2,FALSE) * B12) / 100, "") -> 6.5 | D12: =IFERROR((VLOOKUP(A12,'Food Database'!$A$2:$E$105,3,FALSE) * B12) / 100, "") -> 15 | E12: =IFERROR((VLOOKUP(A12,'Food Database'!$A$2:$E$105,4,FALSE) * B12) / 100, "") -> 0.36 | F12: =IFERROR((VLOOKUP(A12,'Food Database'!$A$2:$E$105,5,FALSE) * B12) / 100, "") -> 89.24
A13: Cooked Basmaty Rice (Larinda) | B13: 200 | C13: =IFERROR((VLOOKUP(A13,'Food Database'!$A$2:$E$105,2,FALSE) * B13) / 100, "") -> 26.1 | D13: =IFERROR((VLOOKUP(A13,'Food Database'!$A$2:$E$105,3,FALSE) * B13) / 100, "") -> 2.9 | E13: =IFERROR((VLOOKUP(A13,'Food Database'!$A$2:$E$105,4,FALSE) * B13) / 100, "") -> 0.4 | F13: =IFERROR((VLOOKUP(A13,'Food Database'!$A$2:$E$105,5,FALSE) * B13) / 100, "") -> 119.6
A14: Skinless, Boneless, Cooked Chicken Breasts | B14: 200 | C14: =IFERROR((VLOOKUP(A14,'Food Database'!$A$2:$E$105,2,FALSE) * B14) / 100, "") -> 0 | D14: =IFERROR((VLOOKUP(A14,'Food Database'!$A$2:$E$105,3,FALSE) * B14) / 100, "") -> 62 | E14: =IFERROR((VLOOKUP(A14,'Food Database'!$A$2:$E$105,4,FALSE) * B14) / 100, "") -> 7.2 | F14: =IFERROR((VLOOKUP(A14,'Food Database'!$A$2:$E$105,5,FALSE) * B14) / 100, "") -> 312.8
A15: Suntop Orange Juice | B15: 250 | C15: =IFERROR((VLOOKUP(A15,'Food Database'!$A$2:$E$105,2,FALSE) * B15) / 100, "") -> 35 | D15: =IFERROR((VLOOKUP(A15,'Food Database'!$A$2:$E$105,3,FALSE) * B15) / 100, "") -> 0 | E15: =IFERROR((VLOOKUP(A15,'Food Database'!$A$2:$E$105,4,FALSE) * B15) / 100, "") -> 0 | F15: =IFERROR((VLOOKUP(A15,'Food Database'!$A$2:$E$105,5,FALSE) * B15) / 100, "") -> 140
A16: Rich Bake Normal Toast (Blue) | B16: 40 | C16: =IFERROR((VLOOKUP(A16,'Food Database'!$A$2:$E$105,2,FALSE) * B16) / 100, "") -> 21.2 | D16: =IFERROR((VLOOKUP(A16,'Food Database'!$A$2:$E$105,3,FALSE) * B16) / 100, "") -> 4.4 | E16: =IFERROR((VLOOKUP(A16,'Food Database'!$A$2:$E$105,4,FALSE) * B16) / 100, "") -> 1.6 | F16: =IFERROR((VLOOKUP(A16,'Food Database'!$A$2:$E$105,5,FALSE) * B16) / 100, "") -> 116.8
A17: Avante Cottage Cheese | B17: 75 | C17: =IFERROR((VLOOKUP(A17,'Food Database'!$A$2:$E$105,2,FALSE) * B17) / 100, "") -> 2.025 | D17: =IFERROR((VLOOKUP(A17,'Food Database'!$A$2:$E$105,3,FALSE) * B17) / 100, "") -> 9.375 | E17: =IFERROR((VLOOKUP(A17,'Food Database'!$A$2:$E$105,4,FALSE) * B17) / 100, "") -> 3.375 | F17: =IFERROR((VLOOKUP(A17,'Food Database'!$A$2:$E$105,5,FALSE) * B17) / 100, "") -> 75.975
A18: Almarai butter bar | B18: =(B13/(B13+125))*10 -> 6.1538462 | C18: =IFERROR((VLOOKUP(A18,'Food Database'!$A$2:$E$105,2,FALSE) * B18) / 100, "") -> 0 | D18: =IFERROR((VLOOKUP(A18,'Food Database'!$A$2:$E$105,3,FALSE) * B18) / 100, "") -> 0 | E18: =IFERROR((VLOOKUP(A18,'Food Database'!$A$2:$E$105,4,FALSE) * B18) / 100, "") -> 4.9230769 | F18: =IFERROR((VLOOKUP(A18,'Food Database'!$A$2:$E$105,5,FALSE) * B18) / 100, "") -> 44.307692
A19: Seuodi extra virgin olive oil | B19: =(B13/(B13+125))*15 -> 9.2307692 | C19: =IFERROR((VLOOKUP(A19,'Food Database'!$A$2:$E$105,2,FALSE) * B19) / 100, "") -> 0 | D19: =IFERROR((VLOOKUP(A19,'Food Database'!$A$2:$E$105,3,FALSE) * B19) / 100, "") -> 0 | E19: =IFERROR((VLOOKUP(A19,'Food Database'!$A$2:$E$105,4,FALSE) * B19) / 100, "") -> 8.5846154 | F19: =IFERROR((VLOOKUP(A19,'Food Database'!$A$2:$E$105,5,FALSE) * B19) / 100, "") -> 77.261538
C20: =IFERROR((VLOOKUP(A20,'Food Database'!$A$2:$E$105,2,FALSE) * B20) / 100, "") | D20: =IFERROR((VLOOKUP(A20,'Food Database'!$A$2:$E$105,3,FALSE) * B20) / 100, "") | E20: =IFERROR((VLOOKUP(A20,'Food Database'!$A$2:$E$105,4,FALSE) * B20) / 100, "") | F20: =IFERROR((VLOOKUP(A20,'Food Database'!$A$2:$E$105,5,FALSE) * B20) / 100, "")
C21: =IFERROR((VLOOKUP(A21,'Food Database'!$A$2:$E$105,2,FALSE) * B21) / 100, "") | D21: =IFERROR((VLOOKUP(A21,'Food Database'!$A$2:$E$105,3,FALSE) * B21) / 100, "") | E21: =IFERROR((VLOOKUP(A21,'Food Database'!$A$2:$E$105,4,FALSE) * B21) / 100, "") | F21: =IFERROR((VLOOKUP(A21,'Food Database'!$A$2:$E$105,5,FALSE) * B21) / 100, "")
C22: =IFERROR((VLOOKUP(A22,'Food Database'!$A$2:$E$105,2,FALSE) * B22) / 100, "") | D22: =IFERROR((VLOOKUP(A22,'Food Database'!$A$2:$E$105,3,FALSE) * B22) / 100, "") | E22: =IFERROR((VLOOKUP(A22,'Food Database'!$A$2:$E$105,4,FALSE) * B22) / 100, "") | F22: =IFERROR((VLOOKUP(A22,'Food Database'!$A$2:$E$105,5,FALSE) * B22) / 100, "")
C23: =IFERROR((VLOOKUP(A23,'Food Database'!$A$2:$E$105,2,FALSE) * B23) / 100, "") | D23: =IFERROR((VLOOKUP(A23,'Food Database'!$A$2:$E$105,3,FALSE) * B23) / 100, "") | E23: =IFERROR((VLOOKUP(A23,'Food Database'!$A$2:$E$105,4,FALSE) * B23) / 100, "") | F23: =IFERROR((VLOOKUP(A23,'Food Database'!$A$2:$E$105,5,FALSE) * B23) / 100, "")
C24: =IFERROR((VLOOKUP(A24,'Food Database'!$A$2:$E$105,2,FALSE) * B24) / 100, "") | D24: =IFERROR((VLOOKUP(A24,'Food Database'!$A$2:$E$105,3,FALSE) * B24) / 100, "") | E24: =IFERROR((VLOOKUP(A24,'Food Database'!$A$2:$E$105,4,FALSE) * B24) / 100, "") | F24: =IFERROR((VLOOKUP(A24,'Food Database'!$A$2:$E$105,5,FALSE) * B24) / 100, "")
C25: =IFERROR((VLOOKUP(A25,'Food Database'!$A$2:$E$105,2,FALSE) * B25) / 100, "") | D25: =IFERROR((VLOOKUP(A25,'Food Database'!$A$2:$E$105,3,FALSE) * B25) / 100, "") | E25: =IFERROR((VLOOKUP(A25,'Food Database'!$A$2:$E$105,4,FALSE) * B25) / 100, "") | F25: =IFERROR((VLOOKUP(A25,'Food Database'!$A$2:$E$105,5,FALSE) * B25) / 100, "")
C26: =IFERROR((VLOOKUP(A26,'Food Database'!$A$2:$E$105,2,FALSE) * B26) / 100, "") | D26: =IFERROR((VLOOKUP(A26,'Food Database'!$A$2:$E$105,3,FALSE) * B26) / 100, "") | E26: =IFERROR((VLOOKUP(A26,'Food Database'!$A$2:$E$105,4,FALSE) * B26) / 100, "") | F26: =IFERROR((VLOOKUP(A26,'Food Database'!$A$2:$E$105,5,FALSE) * B26) / 100, "")
C27: =IFERROR((VLOOKUP(A27,'Food Database'!$A$2:$E$105,2,FALSE) * B27) / 100, "") | D27: =IFERROR((VLOOKUP(A27,'Food Database'!$A$2:$E$105,3,FALSE) * B27) / 100, "") | E27: =IFERROR((VLOOKUP(A27,'Food Database'!$A$2:$E$105,4,FALSE) * B27) / 100, "") | F27: =IFERROR((VLOOKUP(A27,'Food Database'!$A$2:$E$105,5,FALSE) * B27) / 100, "")
C28: =IFERROR((VLOOKUP(A28,'Food Database'!$A$2:$E$105,2,FALSE) * B28) / 100, "") | D28: =IFERROR((VLOOKUP(A28,'Food Database'!$A$2:$E$105,3,FALSE) * B28) / 100, "") | E28: =IFERROR((VLOOKUP(A28,'Food Database'!$A$2:$E$105,4,FALSE) * B28) / 100, "") | F28: =IFERROR((VLOOKUP(A28,'Food Database'!$A$2:$E$105,5,FALSE) * B28) / 100, "")
C29: =IFERROR((VLOOKUP(A29,'Food Database'!$A$2:$E$105,2,FALSE) * B29) / 100, "") | D29: =IFERROR((VLOOKUP(A29,'Food Database'!$A$2:$E$105,3,FALSE) * B29) / 100, "") | E29: =IFERROR((VLOOKUP(A29,'Food Database'!$A$2:$E$105,4,FALSE) * B29) / 100, "") | F29: =IFERROR((VLOOKUP(A29,'Food Database'!$A$2:$E$105,5,FALSE) * B29) / 100, "")
C30: =IFERROR((VLOOKUP(A30,'Food Database'!$A$2:$E$105,2,FALSE) * B30) / 100, "") | D30: =IFERROR((VLOOKUP(A30,'Food Database'!$A$2:$E$105,3,FALSE) * B30) / 100, "") | E30: =IFERROR((VLOOKUP(A30,'Food Database'!$A$2:$E$105,4,FALSE) * B30) / 100, "") | F30: =IFERROR((VLOOKUP(A30,'Food Database'!$A$2:$E$105,5,FALSE) * B30) / 100, "")
C31: =IFERROR((VLOOKUP(A31,'Food Database'!$A$2:$E$105,2,FALSE) * B31) / 100, "") | D31: =IFERROR((VLOOKUP(A31,'Food Database'!$A$2:$E$105,3,FALSE) * B31) / 100, "") | E31: =IFERROR((VLOOKUP(A31,'Food Database'!$A$2:$E$105,4,FALSE) * B31) / 100, "") | F31: =IFERROR((VLOOKUP(A31,'Food Database'!$A$2:$E$105,5,FALSE) * B31) / 100, "")
... C71: =IFERROR((VLOOKUP(A71,'Food Database'!$A$2:$E$105,2,FALSE) * B71) / 100, "") | D71: =IFERROR((VLOOKUP(A71,'Food Database'!$A$2:$E$105,3,FALSE) * B71) / 100, "") | E71: =IFERROR((VLOOKUP(A71,'Food Database'!$A$2:$E$105,4,FALSE) * B71) / 100, "") | F71: =IFERROR((VLOOKUP(A71,'Food Database'!$A$2:$E$105,5,FALSE) * B71) / 100, "")

Sheet Meal Tracker - Nouran
A1: Food | B1: Weight (g) / Volume (ml) | C1: Carbs (g) | D1: Protein (g) | E1: Fats (g) | F1: Calories
A2: Lamar Full-Cream Milk | B2: 85 | C2: =IFERROR((VLOOKUP(A2,'Food Database'!$A$2:$E$105,2,FALSE) * B2) / 100, "") -> 4.08 | D2: =IFERROR((VLOOKUP(A2,'Food Database'!$A$2:$E$105,3,FALSE) * B2) / 100, "") -> 2.805 | E2: =IFERROR((VLOOKUP(A2,'Food Database'!$A$2:$E$105,4,FALSE) * B2) / 100, "") -> 2.55 | F2: =IFERROR((VLOOKUP(A2,'Food Database'!$A$2:$E$105,5,FALSE) * B2) / 100, "") -> 50.49
A3: Digestive Wheat Biscuits | B3: =14.8*2 -> 29.6 | C3: =IFERROR((VLOOKUP(A3,'Food Database'!$A$2:$E$105,2,FALSE) * B3) / 100, "") -> 18.648 | D3: =IFERROR((VLOOKUP(A3,'Food Database'!$A$2:$E$105,3,FALSE) * B3) / 100, "") -> 2.072 | E3: =IFERROR((VLOOKUP(A3,'Food Database'!$A$2:$E$105,4,FALSE) * B3) / 100, "") -> 6.216 | F3: =IFERROR((VLOOKUP(A3,'Food Database'!$A$2:$E$105,5,FALSE) * B3) / 100, "") -> 138.824
A4: Rich Bake Normal Toast (Blue) | B4: 80 | C4: =IFERROR((VLOOKUP(A4,'Food Database'!$A$2:$E$105,2,FALSE) * B4) / 100, "") -> 42.4 | D4: =IFERROR((VLOOKUP(A4,'Food Database'!$A$2:$E$105,3,FALSE) * B4) / 100, "") -> 8.8 | E4: =IFERROR((VLOOKUP(A4,'Food Database'!$A$2:$E$105,4,FALSE) * B4) / 100, "") -> 3.2 | F4: =IFERROR((VLOOKUP(A4,'Food Database'!$A$2:$E$105,5,FALSE) * B4) / 100, "") -> 233.6
A5: Boiled Eggs | B5: 45 | C5: =IFERROR((VLOOKUP(A5,'Food Database'!$A$2:$E$105,2,FALSE) * B5) / 100, "") -> 0.495 | D5: =IFERROR((VLOOKUP(A5,'Food Database'!$A$2:$E$105,3,FALSE) * B5) / 100, "") -> 5.85 | E5: =IFERROR((VLOOKUP(A5,'Food Database'!$A$2:$E$105,4,FALSE) * B5) / 100, "") -> 4.95 | F5: =IFERROR((VLOOKUP(A5,'Food Database'!$A$2:$E$105,5,FALSE) * B5) / 100, "") -> 69.93
A6: Cheddar Cheese | B6: 30 | C6: =IFERROR((VLOOKUP(A6,'Food Database'!$A$2:$E$105,2,FALSE) * B6) / 100, "") -> 0.39 | D6: =IFERROR((VLOOKUP(A6,'Food Database'!$A$2:$E$105,3,FALSE) * B6) / 100, "") -> 7.47 | E6: =IFERROR((VLOOKUP(A6,'Food Database'!$A$2:$E$105,4,FALSE) * B6) / 100, "") -> 9.93 | F6: =IFERROR((VLOOKUP(A6,'Food Database'!$A$2:$E$105,5,FALSE) * B6) / 100, "") -> 120.81
A7: Turkey (cold cut) | B7: 36 | C7: =IFERROR((VLOOKUP(A7,'Food Database'!$A$2:$E$105,2,FALSE) * B7) / 100, "") -> 0.756 | D7: =IFERROR((VLOOKUP(A7,'Food Database'!$A$2:$E$105,3,FALSE) * B7) / 100, "") -> 5.328 | E7: =IFERROR((VLOOKUP(A7,'Food Database'!$A$2:$E$105,4,FALSE) * B7) / 100, "") -> 1.368 | F7: =IFERROR((VLOOKUP(A7,'Food Database'!$A$2:$E$105,5,FALSE) * B7) / 100, "") -> 36.648
A8: Juhayna Pure (Mango & Peach) | B8: 235 | C8: =IFERROR((VLOOKUP(A8,'Food Database'!$A$2:$E$105,2,FALSE) * B8) / 100, "") -> 32.9 | D8: =IFERROR((VLOOKUP(A8,'Food Database'!$A$2:$E$105,3,FALSE) * B8) / 100, "") -> 0.47 | E8: =IFERROR((VLOOKUP(A8,'Food Database'!$A$2:$E$105,4,FALSE) * B8) / 100, "") -> 0.235 | F8: =IFERROR((VLOOKUP(A8,'Food Database'!$A$2:$E$105,5,FALSE) * B8) / 100, "") -> 135.595
A9: Cooked Basmaty Rice (Larinda) | B9: 125 | C9: =IFERROR((VLOOKUP(A9,'Food Database'!$A$2:$E$105,2,FALSE) * B9) / 100, "") -> 16.3125 | D9: =IFERROR((VLOOKUP(A9,'Food Database'!$A$2:$E$105,3,FALSE) * B9) / 100, "") -> 1.8125 | E9: =IFERROR((VLOOKUP(A9,'Food Database'!$A$2:$E$105,4,FALSE) * B9) / 100, "") -> 0.25 | F9: =IFERROR((VLOOKUP(A9,'Food Database'!$A$2:$E$105,5,FALSE) * B9) / 100, "") -> 74.75 | J9: Total Macro-Nutrients
A10: Skinless, Boneless, Cooked Chicken Breasts | B10: 125 | C10: =IFERROR((VLOOKUP(A10,'Food Database'!$A$2:$E$105,2,FALSE) * B10) / 100, "") -> 0 | D10: =IFERROR((VLOOKUP(A10,'Food Database'!$A$2:$E$105,3,FALSE) * B10) / 100, "") -> 38.75 | E10: =IFERROR((VLOOKUP(A10,'Food Database'!$A$2:$E$105,4,FALSE) * B10) / 100, "") -> 4.5 | F10: =IFERROR((VLOOKUP(A10,'Food Database'!$A$2:$E$105,5,FALSE) * B10) / 100, "") -> 195.5 | J10: - | K10: Carbs | L10: Protein | M10: Fats | N10: Calories
A11: Salad (tomato, cucumber, carrot, bell pepper) - rough estimate | B11: 100 | C11: =IFERROR((VLOOKUP(A11,'Food Database'!$A$2:$E$105,2,FALSE) * B11) / 100, "") -> 6 | D11: =IFERROR((VLOOKUP(A11,'Food Database'!$A$2:$E$105,3,FALSE) * B11) / 100, "") -> 1 | E11: =IFERROR((VLOOKUP(A11,'Food Database'!$A$2:$E$105,4,FALSE) * B11) / 100, "") -> 0.2 | F11: =IFERROR((VLOOKUP(A11,'Food Database'!$A$2:$E$105,5,FALSE) * B11) / 100, "") -> 29.8 | J11: Amount (g) | K11: =SUM(C2:C70) -> 144.9815 | L11: =SUM(D2:D70) -> 86.3575 | M11: =SUM(E2:E70) -> 44.541308 | N11: =SUM(F2:F70) -> 1326.2278
A12: Juhayna Mixed Berries Greek Yogurt (180 gm) | B12: 180 | C12: =IFERROR((VLOOKUP(A12,'Food Database'!$A$2:$E$105,2,FALSE) * B12) / 100, "") -> 23 | D12: =IFERROR((VLOOKUP(A12,'Food Database'!$A$2:$E$105,3,FALSE) * B12) / 100, "") -> 12 | E12: =IFERROR((VLOOKUP(A12,'Food Database'!$A$2:$E$105,4,FALSE) * B12) / 100, "") -> 2.7 | F12: =IFERROR((VLOOKUP(A12,'Food Database'!$A$2:$E$105,5,FALSE) * B12) / 100, "") -> 164.3 | J12: Percentage | K12: =(K11*4)/N11 -> 0.43727481 | L12: =(L11*4)/N11 -> 0.26046054 | M12: =(M11*9)/N11 -> 0.30226465 | N12: -
A13: Almarai butter bar | B13: =(B9/(B9+200))*10 -> 3.8461538 | C13: =IFERROR((VLOOKUP(A13,'Food Database'!$A$2:$E$105,2,FALSE) * B13) / 100, "") -> 0 | D13: =IFERROR((VLOOKUP(A13,'Food Database'!$A$2:$E$105,3,FALSE) * B13) / 100, "") -> 0 | E13: =IFERROR((VLOOKUP(A13,'Food Database'!$A$2:$E$105,4,FALSE) * B13) / 100, "") -> 3.0769231 | F13: =IFERROR((VLOOKUP(A13,'Food Database'!$A$2:$E$105,5,FALSE) * B13) / 100, "") -> 27.692308
A14: Seuodi extra virgin olive oil | B14: =(B9/(B9+200))*15 -> 5.7692308 | C14: =IFERROR((VLOOKUP(A14,'Food Database'!$A$2:$E$105,2,FALSE) * B14) / 100, "") -> 0 | D14: =IFERROR((VLOOKUP(A14,'Food Database'!$A$2:$E$105,3,FALSE) * B14) / 100, "") -> 0 | E14: =IFERROR((VLOOKUP(A14,'Food Database'!$A$2:$E$105,4,FALSE) * B14) / 100, "") -> 5.3653846 | F14: =IFERROR((VLOOKUP(A14,'Food Database'!$A$2:$E$105,5,FALSE) * B14) / 100, "") -> 48.288462
C15: =IFERROR((VLOOKUP(A15,'Food Database'!$A$2:$E$105,2,FALSE) * B15) / 100, "") | D15: =IFERROR((VLOOKUP(A15,'Food Database'!$A$2:$E$105,3,FALSE) * B15) / 100, "") | E15: =IFERROR((VLOOKUP(A15,'Food Database'!$A$2:$E$105,4,FALSE) * B15) / 100, "") | F15: =IFERROR((VLOOKUP(A15,'Food Database'!$A$2:$E$105,5,FALSE) * B15) / 100, "")
C16: =IFERROR((VLOOKUP(A16,'Food Database'!$A$2:$E$105,2,FALSE) * B16) / 100, "") | D16: =IFERROR((VLOOKUP(A16,'Food Database'!$A$2:$E$105,3,FALSE) * B16) / 100, "") | E16: =IFERROR((VLOOKUP(A16,'Food Database'!$A$2:$E$105,4,FALSE) * B16) / 100, "") | F16: =IFERROR((VLOOKUP(A16,'Food Database'!$A$2:$E$105,5,FALSE) * B16) / 100, "")
C17: =IFERROR((VLOOKUP(A17,'Food Database'!$A$2:$E$105,2,FALSE) * B17) / 100, "") | D17: =IFERROR((VLOOKUP(A17,'Food Database'!$A$2:$E$105,3,FALSE) * B17) / 100, "") | E17: =IFERROR((VLOOKUP(A17,'Food Database'!$A$2:$E$105,4,FALSE) * B17) / 100, "") | F17: =IFERROR((VLOOKUP(A17,'Food Database'!$A$2:$E$105,5,FALSE) * B17) / 100, "")
C18: =IFERROR((VLOOKUP(A18,'Food Database'!$A$2:$E$105,2,FALSE) * B18) / 100, "") | D18: =IFERROR((VLOOKUP(A18,'Food Database'!$A$2:$E$105,3,FALSE) * B18) / 100, "") | E18: =IFERROR((VLOOKUP(A18,'Food Database'!$A$2:$E$105,4,FALSE) * B18) / 100, "") | F18: =IFERROR((VLOOKUP(A18,'Food Database'!$A$2:$E$105,5,FALSE) * B18) / 100, "")
C19: =IFERROR((VLOOKUP(A19,'Food Database'!$A$2:$E$105,2,FALSE) * B19) / 100, "") | D19: =IFERROR((VLOOKUP(A19,'Food Database'!$A$2:$E$105,3,FALSE) * B19) / 100, "") | E19: =IFERROR((VLOOKUP(A19,'Food Database'!$A$2:$E$105,4,FALSE) * B19) / 100, "") | F19: =IFERROR((VLOOKUP(A19,'Food Database'!$A$2:$E$105,5,FALSE) * B19) / 100, "")
C20: =IFERROR((VLOOKUP(A20,'Food Database'!$A$2:$E$105,2,FALSE) * B20) / 100, "") | D20: =IFERROR((VLOOKUP(A20,'Food Database'!$A$2:$E$105,3,FALSE) * B20) / 100, "") | E20: =IFERROR((VLOOKUP(A20,'Food Database'!$A$2:$E$105,4,FALSE) * B20) / 100, "") | F20: =IFERROR((VLOOKUP(A20,'Food Database'!$A$2:$E$105,5,FALSE) * B20) / 100, "")
C21: =IFERROR((VLOOKUP(A21,'Food Database'!$A$2:$E$105,2,FALSE) * B21) / 100, "") | D21: =IFERROR((VLOOKUP(A21,'Food Database'!$A$2:$E$105,3,FALSE) * B21) / 100, "") | E21: =IFERROR((VLOOKUP(A21,'Food Database'!$A$2:$E$105,4,FALSE) * B21) / 100, "") | F21: =IFERROR((VLOOKUP(A21,'Food Database'!$A$2:$E$105,5,FALSE) * B21) / 100, "")
C22: =IFERROR((VLOOKUP(A22,'Food Database'!$A$2:$E$105,2,FALSE) * B22) / 100, "") | D22: =IFERROR((VLOOKUP(A22,'Food Database'!$A$2:$E$105,3,FALSE) * B22) / 100, "") | E22: =IFERROR((VLOOKUP(A22,'Food Database'!$A$2:$E$105,4,FALSE) * B22) / 100, "") | F22: =IFERROR((VLOOKUP(A22,'Food Database'!$A$2:$E$105,5,FALSE) * B22) / 100, "")
C23: =IFERROR((VLOOKUP(A23,'Food Database'!$A$2:$E$105,2,FALSE) * B23) / 100, "") | D23: =IFERROR((VLOOKUP(A23,'Food Database'!$A$2:$E$105,3,FALSE) * B23) / 100, "") | E23: =IFERROR((VLOOKUP(A23,'Food Database'!$A$2:$E$105,4,FALSE) * B23) / 100, "") | F23: =IFERROR((VLOOKUP(A23,'Food Database'!$A$2:$E$105,5,FALSE) * B23) / 100, "")
C24: =IFERROR((VLOOKUP(A24,'Food Database'!$A$2:$E$105,2,FALSE) * B24) / 100, "") | D24: =IFERROR((VLOOKUP(A24,'Food Database'!$A$2:$E$105,3,FALSE) * B24) / 100, "") | E24: =IFERROR((VLOOKUP(A24,'Food Database'!$A$2:$E$105,4,FALSE) * B24) / 100, "") | F24: =IFERROR((VLOOKUP(A24,'Food Database'!$A$2:$E$105,5,FALSE) * B24) / 100, "")
C25: =IFERROR((VLOOKUP(A25,'Food Database'!$A$2:$E$105,2,FALSE) * B25) / 100, "") | D25: =IFERROR((VLOOKUP(A25,'Food Database'!$A$2:$E$105,3,FALSE) * B25) / 100, "") | E25: =IFERROR((VLOOKUP(A25,'Food Database'!$A$2:$E$105,4,FALSE) * B25) / 100, "") | F25: =IFERROR((VLOOKUP(A25,'Food Database'!$A$2:$E$105,5,FALSE) * B25) / 100, "")
C26: =IFERROR((VLOOKUP(A26,'Food Database'!$A$2:$E$105,2,FALSE) * B26) / 100, "") | D26: =IFERROR((VLOOKUP(A26,'Food Database'!$A$2:$E$105,3,FALSE) * B26) / 100, "") | E26: =IFERROR((VLOOKUP(A26,'Food Database'!$A$2:$E$105,4,FALSE) * B26) / 100, "") | F26: =IFERROR((VLOOKUP(A26,'Food Database'!$A$2:$E$105,5,FALSE) * B26) / 100, "")
... C71: =IFERROR((VLOOKUP(A71,'Food Database'!$A$2:$E$105,2,FALSE) * B71) / 100, "") | D71: =IFERROR((VLOOKUP(A71,'Food Database'!$A$2:$E$105,3,FALSE) * B71) / 100, "") | E71: =IFERROR((VLOOKUP(A71,'Food Database'!$A$2:$E$105,4,FALSE) * B71) / 100, "") | F71: =IFERROR((VLOOKUP(A71,'Food Database'!$A$2:$E$105,5,FALSE) * B71) / 100, "")

Sheet Trying to reduce cost
A1: Food | B1: Weight (g) / Volume (ml) | C1: Carbs (g) | D1: Protein (g) | E1: Fats (g) | F1: Calories
A2: Bread (Baladi or Shami) | B2: 75 | C2: =IFERROR((VLOOKUP(A2,'Food Database'!$A$2:$E$105,2,FALSE) * B2) / 100, "") -> 41.25 | D2: =IFERROR((VLOOKUP(A2,'Food Database'!$A$2:$E$105,3,FALSE) * B2) / 100, "") -> 6.75 | E2: =IFERROR((VLOOKUP(A2,'Food Database'!$A$2:$E$105,4,FALSE) * B2) / 100, "") -> 1.5 | F2: =IFERROR((VLOOKUP(A2,'Food Database'!$A$2:$E$105,5,FALSE) * B2) / 100, "") -> 205.5
A3: Egyptian Roumy Cheese | B3: 70 | C3: =IFERROR((VLOOKUP(A3,'Food Database'!$A$2:$E$105,2,FALSE) * B3) / 100, "") -> 0.7 | D3: =IFERROR((VLOOKUP(A3,'Food Database'!$A$2:$E$105,3,FALSE) * B3) / 100, "") -> 17.5 | E3: =IFERROR((VLOOKUP(A3,'Food Database'!$A$2:$E$105,4,FALSE) * B3) / 100, "") -> 21 | F3: =IFERROR((VLOOKUP(A3,'Food Database'!$A$2:$E$105,5,FALSE) * B3) / 100, "") -> 261.8
A4: Boiled Eggs | B4: 90 | C4: =IFERROR((VLOOKUP(A4,'Food Database'!$A$2:$E$105,2,FALSE) * B4) / 100, "") -> 0.99 | D4: =IFERROR((VLOOKUP(A4,'Food Database'!$A$2:$E$105,3,FALSE) * B4) / 100, "") -> 11.7 | E4: =IFERROR((VLOOKUP(A4,'Food Database'!$A$2:$E$105,4,FALSE) * B4) / 100, "") -> 9.9 | F4: =IFERROR((VLOOKUP(A4,'Food Database'!$A$2:$E$105,5,FALSE) * B4) / 100, "") -> 139.86
A5: Bell Pepper | B5: 80 | C5: =IFERROR((VLOOKUP(A5,'Food Database'!$A$2:$E$105,2,FALSE) * B5) / 100, "") -> 4.8 | D5: =IFERROR((VLOOKUP(A5,'Food Database'!$A$2:$E$105,3,FALSE) * B5) / 100, "") -> 0.8 | E5: =IFERROR((VLOOKUP(A5,'Food Database'!$A$2:$E$105,4,FALSE) * B5) / 100, "") -> 0.24 | F5: =IFERROR((VLOOKUP(A5,'Food Database'!$A$2:$E$105,5,FALSE) * B5) / 100, "") -> 24.56
A6: Carrots | B6: 85 | C6: =IFERROR((VLOOKUP(A6,'Food Database'!$A$2:$E$105,2,FALSE) * B6) / 100, "") -> 8.5 | D6: =IFERROR((VLOOKUP(A6,'Food Database'!$A$2:$E$105,3,FALSE) * B6) / 100, "") -> 0.765 | E6: =IFERROR((VLOOKUP(A6,'Food Database'!$A$2:$E$105,4,FALSE) * B6) / 100, "") -> 0.17 | F6: =IFERROR((VLOOKUP(A6,'Food Database'!$A$2:$E$105,5,FALSE) * B6) / 100, "") -> 38.59
A7: Banana Milk | B7: 200 | C7: =IFERROR((VLOOKUP(A7,'Food Database'!$A$2:$E$105,2,FALSE) * B7) / 100, "") -> 23 | D7: =IFERROR((VLOOKUP(A7,'Food Database'!$A$2:$E$105,3,FALSE) * B7) / 100, "") -> 6 | E7: =IFERROR((VLOOKUP(A7,'Food Database'!$A$2:$E$105,4,FALSE) * B7) / 100, "") -> 3 | F7: =IFERROR((VLOOKUP(A7,'Food Database'!$A$2:$E$105,5,FALSE) * B7) / 100, "") -> 143
A8: Kayy Oats | B8: 100 | C8: =IFERROR((VLOOKUP(A8,'Food Database'!$A$2:$E$105,2,FALSE) * B8) / 100, "") -> 60.4 | D8: =IFERROR((VLOOKUP(A8,'Food Database'!$A$2:$E$105,3,FALSE) * B8) / 100, "") -> 30 | E8: =IFERROR((VLOOKUP(A8,'Food Database'!$A$2:$E$105,4,FALSE) * B8) / 100, "") -> 2 | F8: =IFERROR((VLOOKUP(A8,'Food Database'!$A$2:$E$105,5,FALSE) * B8) / 100, "") -> 379.6 | J8: Total Macro-Nutrients
A9: Lamar Full-Cream Milk | B9: 165 | C9: =IFERROR((VLOOKUP(A9,'Food Database'!$A$2:$E$105,2,FALSE) * B9) / 100, "") -> 7.92 | D9: =IFERROR((VLOOKUP(A9,'Food Database'!$A$2:$E$105,3,FALSE) * B9) / 100, "") -> 5.445 | E9: =IFERROR((VLOOKUP(A9,'Food Database'!$A$2:$E$105,4,FALSE) * B9) / 100, "") -> 4.95 | F9: =IFERROR((VLOOKUP(A9,'Food Database'!$A$2:$E$105,5,FALSE) * B9) / 100, "") -> 98.01 | J9: - | K9: Carbs | L9: Protein | M9: Fats | N9: Calories
A10: Honey | B10: 8 | C10: =IFERROR((VLOOKUP(A10,'Food Database'!$A$2:$E$105,2,FALSE) * B10) / 100, "") -> 6.592 | D10: =IFERROR((VLOOKUP(A10,'Food Database'!$A$2:$E$105,3,FALSE) * B10) / 100, "") -> 0.024 | E10: =IFERROR((VLOOKUP(A10,'Food Database'!$A$2:$E$105,4,FALSE) * B10) / 100, "") -> 0 | F10: =IFERROR((VLOOKUP(A10,'Food Database'!$A$2:$E$105,5,FALSE) * B10) / 100, "") -> 26.464 | J10: Amount (g) | K10: =SUM(C2:C70) -> 246.517 | L10: =SUM(D2:D70) -> 164.499 | M10: =SUM(E2:E70) -> 85.282692 | N10: =SUM(F2:F70) -> 2411.6082
A11: Walnuts | B11: =2.5*8 -> 20 | C11: =IFERROR((VLOOKUP(A11,'Food Database'!$A$2:$E$105,2,FALSE) * B11) / 100, "") -> 2.74 | D11: =IFERROR((VLOOKUP(A11,'Food Database'!$A$2:$E$105,3,FALSE) * B11) / 100, "") -> 3.04 | E11: =IFERROR((VLOOKUP(A11,'Food Database'!$A$2:$E$105,4,FALSE) * B11) / 100, "") -> 13.04 | F11: =IFERROR((VLOOKUP(A11,'Food Database'!$A$2:$E$105,5,FALSE) * B11) / 100, "") -> 140.48 | J11: Percentage | K11: =(K10*4)/N10 -> 0.40888399 | L11: =(L10*4)/N10 -> 0.27284531 | M11: =(M10*9)/N10 -> 0.3182707 | N11: -
A12: Juhayna Full Cream Yogurt (105 gm) | B12: 105 | C12: =IFERROR((VLOOKUP(A12,'Food Database'!$A$2:$E$105,2,FALSE) * B12) / 100, "") -> 5.3 | D12: =IFERROR((VLOOKUP(A12,'Food Database'!$A$2:$E$105,3,FALSE) * B12) / 100, "") -> 3.8 | E12: =IFERROR((VLOOKUP(A12,'Food Database'!$A$2:$E$105,4,FALSE) * B12) / 100, "") -> 3.4 | F12: =IFERROR((VLOOKUP(A12,'Food Database'!$A$2:$E$105,5,FALSE) * B12) / 100, "") -> 67
A13: Cooked Basmaty Rice (Larinda) | B13: 200 | C13: =IFERROR((VLOOKUP(A13,'Food Database'!$A$2:$E$105,2,FALSE) * B13) / 100, "") -> 26.1 | D13: =IFERROR((VLOOKUP(A13,'Food Database'!$A$2:$E$105,3,FALSE) * B13) / 100, "") -> 2.9 | E13: =IFERROR((VLOOKUP(A13,'Food Database'!$A$2:$E$105,4,FALSE) * B13) / 100, "") -> 0.4 | F13: =IFERROR((VLOOKUP(A13,'Food Database'!$A$2:$E$105,5,FALSE) * B13) / 100, "") -> 119.6
A14: Skinless, Boneless, Cooked Chicken Breasts | B14: 200 | C14: =IFERROR((VLOOKUP(A14,'Food Database'!$A$2:$E$105,2,FALSE) * B14) / 100, "") -> 0 | D14: =IFERROR((VLOOKUP(A14,'Food Database'!$A$2:$E$105,3,FALSE) * B14) / 100, "") -> 62 | E14: =IFERROR((VLOOKUP(A14,'Food Database'!$A$2:$E$105,4,FALSE) * B14) / 100, "") -> 7.2 | F14: =IFERROR((VLOOKUP(A14,'Food Database'!$A$2:$E$105,5,FALSE) * B14) / 100, "") -> 312.8
A15: Suntop Orange Juice | B15: 250 | C15: =IFERROR((VLOOKUP(A15,'Food Database'!$A$2:$E$105,2,FALSE) * B15) / 100, "") -> 35 | D15: =IFERROR((VLOOKUP(A15,'Food Database'!$A$2:$E$105,3,FALSE) * B15) / 100, "") -> 0 | E15: =IFERROR((VLOOKUP(A15,'Food Database'!$A$2:$E$105,4,FALSE) * B15) / 100, "") -> 0 | F15: =IFERROR((VLOOKUP(A15,'Food Database'!$A$2:$E$105,5,FALSE) * B15) / 100, "") -> 140
A16: Rich Bake Normal Toast (Blue) | B16: 40 | C16: =IFERROR((VLOOKUP(A16,'Food Database'!$A$2:$E$105,2,FALSE) * B16) / 100, "") -> 21.2 | D16: =IFERROR((VLOOKUP(A16,'Food Database'!$A$2:$E$105,3,FALSE) * B16) / 100, "") -> 4.4 | E16: =IFERROR((VLOOKUP(A16,'Food Database'!$A$2:$E$105,4,FALSE) * B16) / 100, "") -> 1.6 | F16: =IFERROR((VLOOKUP(A16,'Food Database'!$A$2:$E$105,5,FALSE) * B16) / 100, "") -> 116.8
A17: Avante Cottage Cheese | B17: 75 | C17: =IFERROR((VLOOKUP(A17,'Food Database'!$A$2:$E$105,2,FALSE) * B17) / 100, "") -> 2.025 | D17: =IFERROR((VLOOKUP(A17,'Food Database'!$A$2:$E$105,3,FALSE) * B17) / 100, "") -> 9.375 | E17: =IFERROR((VLOOKUP(A17,'Food Database'!$A$2:$E$105,4,FALSE) * B17) / 100, "") -> 3.375 | F17: =IFERROR((VLOOKUP(A17,'Food Database'!$A$2:$E$105,5,FALSE) * B17) / 100, "") -> 75.975
A18: Almarai butter bar | B18: =(B13/(B13+125))*10 -> 6.1538462 | C18: =IFERROR((VLOOKUP(A18,'Food Database'!$A$2:$E$105,2,FALSE) * B18) / 100, "") -> 0 | D18: =IFERROR((VLOOKUP(A18,'Food Database'!$A$2:$E$105,3,FALSE) * B18) / 100, "") -> 0 | E18: =IFERROR((VLOOKUP(A18,'Food Database'!$A$2:$E$105,4,FALSE) * B18) / 100, "") -> 4.9230769 | F18: =IFERROR((VLOOKUP(A18,'Food Database'!$A$2:$E$105,5,FALSE) * B18) / 100, "") -> 44.307692
A19: Seuodi extra virgin olive oil | B19: =(B13/(B13+125))*15 -> 9.2307692 | C19: =IFERROR((VLOOKUP(A19,'Food Database'!$A$2:$E$105,2,FALSE) * B19) / 100, "") -> 0 | D19: =IFERROR((VLOOKUP(A19,'Food Database'!$A$2:$E$105,3,FALSE) * B19) / 100, "") -> 0 | E19: =IFERROR((VLOOKUP(A19,'Food Database'!$A$2:$E$105,4,FALSE) * B19) / 100, "") -> 8.5846154 | F19: =IFERROR((VLOOKUP(A19,'Food Database'!$A$2:$E$105,5,FALSE) * B19) / 100, "") -> 77.261538
C20: =IFERROR((VLOOKUP(A20,'Food Database'!$A$2:$E$105,2,FALSE) * B20) / 100, "") | D20: =IFERROR((VLOOKUP(A20,'Food Database'!$A$2:$E$105,3,FALSE) * B20) / 100, "") | E20: =IFERROR((VLOOKUP(A20,'Food Database'!$A$2:$E$105,4,FALSE) * B20) / 100, "") | F20: =IFERROR((VLOOKUP(A20,'Food Database'!$A$2:$E$105,5,FALSE) * B20) / 100, "")
C21: =IFERROR((VLOOKUP(A21,'Food Database'!$A$2:$E$105,2,FALSE) * B21) / 100, "") | D21: =IFERROR((VLOOKUP(A21,'Food Database'!$A$2:$E$105,3,FALSE) * B21) / 100, "") | E21: =IFERROR((VLOOKUP(A21,'Food Database'!$A$2:$E$105,4,FALSE) * B21) / 100, "") | F21: =IFERROR((VLOOKUP(A21,'Food Database'!$A$2:$E$105,5,FALSE) * B21) / 100, "")
C22: =IFERROR((VLOOKUP(A22,'Food Database'!$A$2:$E$105,2,FALSE) * B22) / 100, "") | D22: =IFERROR((VLOOKUP(A22,'Food Database'!$A$2:$E$105,3,FALSE) * B22) / 100, "") | E22: =IFERROR((VLOOKUP(A22,'Food Database'!$A$2:$E$105,4,FALSE) * B22) / 100, "") | F22: =IFERROR((VLOOKUP(A22,'Food Database'!$A$2:$E$105,5,FALSE) * B22) / 100, "")
C23: =IFERROR((VLOOKUP(A23,'Food Database'!$A$2:$E$105,2,FALSE) * B23) / 100, "") | D23: =IFERROR((VLOOKUP(A23,'Food Database'!$A$2:$E$105,3,FALSE) * B23) / 100, "") | E23: =IFERROR((VLOOKUP(A23,'Food Database'!$A$2:$E$105,4,FALSE) * B23) / 100, "") | F23: =IFERROR((VLOOKUP(A23,'Food Database'!$A$2:$E$105,5,FALSE) * B23) / 100, "")
C24: =IFERROR((VLOOKUP(A24,'Food Database'!$A$2:$E$105,2,FALSE) * B24) / 100, "") | D24: =IFERROR((VLOOKUP(A24,'Food Database'!$A$2:$E$105,3,FALSE) * B24) / 100, "") | E24: =IFERROR((VLOOKUP(A24,'Food Database'!$A$2:$E$105,4,FALSE) * B24) / 100, "") | F24: =IFERROR((VLOOKUP(A24,'Food Database'!$A$2:$E$105,5,FALSE) * B24) / 100, "")
C25: =IFERROR((VLOOKUP(A25,'Food Database'!$A$2:$E$105,2,FALSE) * B25) / 100, "") | D25: =IFERROR((VLOOKUP(A25,'Food Database'!$A$2:$E$105,3,FALSE) * B25) / 100, "") | E25: =IFERROR((VLOOKUP(A25,'Food Database'!$A$2:$E$105,4,FALSE) * B25) / 100, "") | F25: =IFERROR((VLOOKUP(A25,'Food Database'!$A$2:$E$105,5,FALSE) * B25) / 100, "")
C26: =IFERROR((VLOOKUP(A26,'Food Database'!$A$2:$E$105,2,FALSE) * B26) / 100, "") | D26: =IFERROR((VLOOKUP(A26,'Food Database'!$A$2:$E$105,3,FALSE) * B26) / 100, "") | E26: =IFERROR((VLOOKUP(A26,'Food Database'!$A$2:$E$105,4,FALSE) * B26) / 100, "") | F26: =IFERROR((VLOOKUP(A26,'Food Database'!$A$2:$E$105,5,FALSE) * B26) / 100, "")
C27: =IFERROR((VLOOKUP(A27,'Food Database'!$A$2:$E$105,2,FALSE) * B27) / 100, "") | D27: =IFERROR((VLOOKUP(A27,'Food Database'!$A$2:$E$105,3,FALSE) * B27) / 100, "") | E27: =IFERROR((VLOOKUP(A27,'Food Database'!$A$2:$E$105,4,FALSE) * B27) / 100, "") | F27: =IFERROR((VLOOKUP(A27,'Food Database'!$A$2:$E$105,5,FALSE) * B27) / 100, "")
C28: =IFERROR((VLOOKUP(A28,'Food Database'!$A$2:$E$105,2,FALSE) * B28) / 100, "") | D28: =IFERROR((VLOOKUP(A28,'Food Database'!$A$2:$E$105,3,FALSE) * B28) / 100, "") | E28: =IFERROR((VLOOKUP(A28,'Food Database'!$A$2:$E$105,4,FALSE) * B28) / 100, "") | F28: =IFERROR((VLOOKUP(A28,'Food Database'!$A$2:$E$105,5,FALSE) * B28) / 100, "")
C29: =IFERROR((VLOOKUP(A29,'Food Database'!$A$2:$E$105,2,FALSE) * B29) / 100, "") | D29: =IFERROR((VLOOKUP(A29,'Food Database'!$A$2:$E$105,3,FALSE) * B29) / 100, "") | E29: =IFERROR((VLOOKUP(A29,'Food Database'!$A$2:$E$105,4,FALSE) * B29) / 100, "") | F29: =IFERROR((VLOOKUP(A29,'Food Database'!$A$2:$E$105,5,FALSE) * B29) / 100, "")
C30: =IFERROR((VLOOKUP(A30,'Food Database'!$A$2:$E$105,2,FALSE) * B30) / 100, "") | D30: =IFERROR((VLOOKUP(A30,'Food Database'!$A$2:$E$105,3,FALSE) * B30) / 100, "") | E30: =IFERROR((VLOOKUP(A30,'Food Database'!$A$2:$E$105,4,FALSE) * B30) / 100, "") | F30: =IFERROR((VLOOKUP(A30,'Food Database'!$A$2:$E$105,5,FALSE) * B30) / 100, "")
C31: =IFERROR((VLOOKUP(A31,'Food Database'!$A$2:$E$105,2,FALSE) * B31) / 100, "") | D31: =IFERROR((VLOOKUP(A31,'Food Database'!$A$2:$E$105,3,FALSE) * B31) / 100, "") | E31: =IFERROR((VLOOKUP(A31,'Food Database'!$A$2:$E$105,4,FALSE) * B31) / 100, "") | F31: =IFERROR((VLOOKUP(A31,'Food Database'!$A$2:$E$105,5,FALSE) * B31) / 100, "")
... C71: =IFERROR((VLOOKUP(A71,'Food Database'!$A$2:$E$105,2,FALSE) * B71) / 100, "") | D71: =IFERROR((VLOOKUP(A71,'Food Database'!$A$2:$E$105,3,FALSE) * B71) / 100, "") | E71: =IFERROR((VLOOKUP(A71,'Food Database'!$A$2:$E$105,4,FALSE) * B71) / 100, "") | F71: =IFERROR((VLOOKUP(A71,'Food Database'!$A$2:$E$105,5,FALSE) * B71) / 100, "")
