Workbook
Name Base_Annual_Salary_GBP: Inputs!$B$2
Name Bonus_Pct_Aug2026_to_Sep2026: Inputs!$B$61
Name Bonus_Pct_Oct2026_to_Sep2027: Inputs!$B$62
Name Bonus_Pct_Oct2027_to_Sep2028: Inputs!$B$63
Name Bonus_Pct_Oct2028_to_Sep2029: Inputs!$B$64
Name Bonus_Pct_Oct2029_onwards: Inputs!$B$65
Name FX_USD_per_GBP: Inputs!$B$13
Name Include_Pension_in_Cashflow: Inputs!$B$16
Name Living_Expenses_EGP_Monthly_2026: [1]Inputs!$B$24
Name Living_Expenses_EGP_Monthly_2027: [1]Inputs!$B$25
Name Living_Expenses_EGP_Monthly_2028: [1]Inputs!$B$26
Name Living_Expenses_EGP_Monthly_2029: [1]Inputs!$B$27
Name Living_Expenses_EGP_Monthly_2030: [1]Inputs!$B$28
Name Living_Expenses_GBP_Monthly_2026: Inputs!$B$50
Name Living_Expenses_GBP_Monthly_2027: Inputs!$B$51
Name Living_Expenses_GBP_Monthly_2028: Inputs!$B$52
Name Living_Expenses_GBP_Monthly_2029: Inputs!$B$53
Name Living_Expenses_GBP_Monthly_2030: Inputs!$B$54
Name New_Hire_Stock_Grant_USD: Inputs!$B$12
Name Raise_Pct_Apr2027: Inputs!$B$4
Name Raise_Pct_Apr2028: Inputs!$B$5
Name Raise_Pct_Apr2029: Inputs!$B$6
Name Raise_Pct_Apr2030: Inputs!$B$7
Name Raise_Pct_Nov2027: Inputs!$B$25
Name Raise_Pct_Nov2028: Inputs!$B$26
Name Raise_Pct_Nov2029: Inputs!$B$27
Name Raise_Pct_Nov2030: Inputs!$B$28
Name RSU_Grant_Nov2027_USD: Inputs!$B$31
Name RSU_Grant_Nov2028_USD: Inputs!$B$32
Name RSU_Grant_Nov2029_USD: Inputs!$B$33
Name RSU_Price_Change_Pct: Inputs!$B$15
Name Taxes_Pct: Inputs!#REF!
Name UK_Additional_Rate: Inputs!$B$41
Name UK_Basic_Band_Upper_Annual: Inputs!$B$37
Name UK_Basic_Rate: Inputs!$B$39
Name UK_Higher_Band_Upper_Annual: Inputs!$B$38
Name UK_Higher_Rate: Inputs!$B$40
Name UK_NI_Main_Rate: Inputs!$B$45
Name UK_NI_PT_Monthly: Inputs!$B$43
Name UK_NI_UEL_Monthly: Inputs!$B$44
Name UK_NI_Upper_Rate: Inputs!$B$46
Name UK_Personal_Allowance_Annual: Inputs!$B$36
Name UK_TaxYear_Start_Month: Inputs!$B$42
Name USD_to_EGP: [1]Inputs!$B$29

Sheet Inputs
A1: Key | B1: Value | C1: Notes
A2: Base_Annual_Salary_GBP | B2: 50000 | C2: Base salary (annual) in GBP
A4: Raise_Pct_Apr2027 | B4: 0.03 | C4: Annual salary review (March), effective April 2027.
A5: Raise_Pct_Apr2028 | B5: 0.03 | C5: Annual salary review (March), effective April 2028.
A6: Raise_Pct_Apr2029 | B6: 0.03 | C6: Annual salary review (March), effective April 2029.
A7: Raise_Pct_Apr2030 | B7: 0.03 | C7: Annual salary review (March), effective April 2030.
A8: Hiring_Bonus_GBP | B8: 3000 | C8: One-off hiring bonus
A9: Hiring_Bonus_Pay_Month_Offset | B9: 0 | C9: Months after Aug 2026 (0=Aug 2026)
A10: Relocation_Allowance_GBP | B10: 0 | C10: Relocation allowance
A11: Relocation_Pay_Month_Offset | B11: 0 | C11: Months after Aug 2026 (0=Aug 2026)
A12: New_Hire_Stock_Grant_USD | B12: 30000 | C12: New-hire RSU grant face value (USD)
A13: FX_USD_per_GBP | B13: 1.36 | C13: FX: RSU_GBP = USD / FX
A15: RSU_Assumed_Price_Change_Pct_per_year | B15: 0 | C15: Optional price change assumption for RSU (default 0%)
... A20: NI_Passback_Pct_of_Employee_Contrib | B20: 0.07 | C20: NI passback fraction of employee contrib
A24: Raises – Off-cycle (effective October)
A25: Raise_Pct_Nov2027 | B25: 0 | C25: Off-cycle review (Oct) effective Oct 2027 (optional).
A26: Raise_Pct_Nov2028 | B26: 0.03 | C26: Off-cycle review (Oct) effective Oct 2028 (optional).
A27: Raise_Pct_Nov2029 | B27: 0 | C27: Off-cycle review (Oct) effective Oct 2029 (optional).
A28: Raise_Pct_Nov2030 | B28: 0 | C28: Off-cycle review (Oct) effective Oct 2030 (optional).
A30: RSU Refresh Grants (Optional, USD)
A31: RSU_Grant_Nov2027_USD | B31: 0 | C31: Grant in Nov 2027 (no guarantee). First vest Nov 2028.
A32: RSU_Grant_Nov2028_USD | B32: 0 | C32: Grant in Nov 2028 (no guarantee). First vest Nov 2029.
A33: RSU_Grant_Nov2029_USD | B33: 0 | C33: Grant in Nov 2029 (no guarantee). First vest Nov 2030.
A35: UK Tax Settings (England/Wales/NI, 2026/27)
A36: UK_Personal_Allowance_Annual | B36: 12570 | C36: Personal Allowance (annual)
A37: UK_Basic_Band_Upper_Annual | B37: 50270 | C37: Upper limit of Basic rate band (annual, incl allowance)
A38: UK_Higher_Band_Upper_Annual | B38: 125140 | C38: Upper limit of Higher rate band (annual)
A39: UK_Basic_Rate | B39: 0.2 | C39: Income Tax basic rate
A40: UK_Higher_Rate | B40: 0.4 | C40: Income Tax higher rate
A41: UK_Additional_Rate | B41: 0.45 | C41: Income Tax additional rate
A42: UK_TaxYear_Start_Month | B42: 4 | C42: Tax year starts in April
A43: UK_NI_PT_Monthly | B43: 1048 | C43: NI Primary Threshold (per month)
A44: UK_NI_UEL_Monthly | B44: 4189 | C44: NI Upper Earnings Limit (per month)
A45: UK_NI_Main_Rate | B45: 0.08 | C45: NI rate between PT and UEL
A46: UK_NI_Upper_Rate | B46: 0.02 | C46: NI rate above UEL
A50: Living_Expenses_GBP_Monthly_2026 | B50: =2400 -> 2400
A51: Living_Expenses_GBP_Monthly_2027 | B51: =B50*1.02 -> 2448 | E51: Assumed living expenses
A52: Living_Expenses_GBP_Monthly_2028 | B52: =B51*1.02 -> 2496.96 | E52: Element | F52: Price | G52: Assumptions
A53: Living_Expenses_GBP_Monthly_2029 | B53: =B52*1.02 -> 2546.8992 | E53: Rent | F53: =1050+215 -> 1265 | G53: Rent + Council Tax
A54: Living_Expenses_GBP_Monthly_2030 | B54: =B53*1.02 -> 2597.8372 | E54: Utilities (electricity/gas) | F54: 160
...

Sheet Monthly Schedule
A1: Month | B1: Base Salary (GBP) | C1: Bonus Paid (GBP) | D1: RSU Vest (GBP) | E1: Hiring Bonus (GBP) | F1: Relocation (GBP) | G1: Pension Employer (GBP) | H1: Total Gross Monthly Income | I1: Total Net Monthly Income | J1: Income Tax (PAYE, GBP) | K1: Employee NI (GBP) | L1: Bonus Target Pct (current)
A2: 46235 | B2: =(IF(YEAR($A2)=2026,Base_Annual_Salary_GBP,IF(YEAR($A2)=2027,Base_Annual_Salary_GBP*(IF(MONTH($A2)>=4,(1+Raise_Pct_Apr2027),1)*IF(MONTH($A2)>=10,(1+Raise_Pct_Nov2027),1)),IF(YEAR($A2)=2028,Base_Annual_Salary_GBP*((1+Raise_Pct_Apr2027)*(1+Raise_Pct_Nov2027))*(IF(MONTH($A2)>=4,(1+Raise_Pct_Apr2028),1)*IF(MONTH($A2)>=10,(1+Raise_Pct_Nov2028),1)),IF(YEAR($A2)=2029,Base_Annual_Salary_GBP*((1+Raise_Pct_Apr2027)*(1+Raise_Pct_Nov2027)*(1+Raise_Pct_Apr2028)*(1+Raise_Pct_Nov2028))*(IF(MONTH($A2)>=4,(1+Raise_Pct_Apr2029),1)*IF(MONTH($A2)>=10,(1+Raise_Pct_Nov2029),1)),Base_Annual_Salary_GBP*((1+Raise_Pct_Apr2027)*(1+Raise_Pct_Nov2027)*(1+Raise_Pct_Apr2028)*(1+Raise_Pct_Nov2028)*(1+Raise_Pct_Apr2029)*(1+Raise_Pct_Nov2029))*(IF(MONTH($A2)>=4,(1+Raise_Pct_Apr2030),1)*IF(MONTH($A2)>=10,(1+Raise_Pct_Nov2030),1)))))))/12 -> 4166.6667 | C2: =IF(MONTH($A2)=11,((IF(DATE(YEAR($A2),4,1)<DATE(2026,10,1),Bonus_Pct_Aug2026_to_Sep2026,IF(DATE(YEAR($A2),4,1)<DATE(2027,10,1),Bonus_Pct_Oct2026_to_Sep2027,IF(DATE(YEAR($A2),4,1)<DATE(2028,10,1),Bonus_Pct_Oct2027_to_Sep2028,IF(DATE(YEAR($A2),4,1)<DATE(2029,10,1),Bonus_Pct_Oct2028_to_Sep2029,Bonus_Pct_Oct2029_onwards)))))/2)*($B2*12) / (1 + IF(YEAR($A2)=2027,Raise_Pct_Nov2027,IF(YEAR($A2)=2028,Raise_Pct_Nov2028,IF(YEAR($A2)=2029,Raise_Pct_Nov2029,IF(YEAR($A2)=2030,Raise_Pct_Nov2030,0))))) * IF(YEAR($A2)=2026,2/6,1),IF(MONTH($A2)=5,((IF(DATE(YEAR($A2)-1,10,1)<DATE(2026,10,1),Bonus_Pct_Aug2026_to_Sep2026,IF(DATE(YEAR($A2)-1,10,1)<DATE(2027,10,1),Bonus_Pct_Oct2026_to_Sep2027,IF(DATE(YEAR($A2)-1,10,1)<DATE(2028,10,1),Bonus_Pct_Oct2027_to_Sep2028,IF(DATE(YEAR($A2)-1,10,1)<DATE(2029,10,1),Bonus_Pct_Oct2028_to_Sep2029,Bonus_Pct_Oct2029_onwards)))))/2)*($B2*12) / (1 + IF(YEAR($A2)=2027,Raise_Pct_Apr2027,IF(YEAR($A2)=2028,Raise_Pct_Apr2028,IF(YEAR($A2)=2029,Raise_Pct_Apr2029,IF(YEAR($A2)=2030,Raise_Pct_Apr2030,0))))),0)) -> 0 | D2: =IF(OR($A2=DATE(2027,9,1),$A2=EDATE(DATE(2027,9,1),12),$A2=EDATE(DATE(2027,9,1),24)),(New_Hire_Stock_Grant_USD/3)/FX_USD_per_GBP*(1+IF(YEAR($A2)=2027,Inputs!$B$56,IF(YEAR($A2)=2028,Inputs!$B$57,IF(YEAR($A2)=2029,Inputs!$B$58,0)))),0)+IF(OR($A2=DATE(2028,11,1),$A2=DATE(2029,11,1),$A2=DATE(2030,11,1)),(RSU_Grant_Nov2027_USD/3)/FX_USD_per_GBP*(1+RSU_Price_Change_Pct)^(YEAR($A2)-2028),0)+IF(OR($A2=DATE(2029,11,1),$A2=DATE(2030,11,1)),(RSU_Grant_Nov2028_USD/3)/FX_USD_per_GBP*(1+RSU_Price_Change_Pct)^(YEAR($A2)-2029),0)+IF($A2=DATE(2030,11,1),(RSU_Grant_Nov2029_USD/3)/FX_USD_per_GBP*(1+RSU_Price_Change_Pct)^(YEAR($A2)-2030),0) -> 0 | E2: =IF($A2=EDATE(DATE(2026,8,1),Inputs!$B$9),Inputs!$B$8,0) -> 3000 | F2: =IF($A2=EDATE(DATE(2026,8,1),Inputs!$B$11),Inputs!$B$10,0) -> 0 | G2: =IF(Inputs!$B$16=1,((IF(YEAR($A2)=2026,Inputs!$B$2,IF(YEAR($A2)=2027,IF(MONTH($A2)>=Inputs!#REF!,Inputs!$B$2*(1+Inputs!$B$4),Inputs!$B$2),IF(YEAR($A2)=2028,IF(MONTH($A2)>=Inputs!#REF!,Inputs!$B$2*(1+Inputs!$B$4)*(1+Inputs!$B$5),Inputs!$B$2*(1+Inputs!$B$4)),IF(YEAR($A2)=2029,IF(MONTH($A2)>=Inputs!#REF!,Inputs!$B$2*(1+Inputs!$B$4)*(1+Inputs!$B$5)*(1+Inputs!$B$6),Inputs!$B$2*(1+Inputs!$B$4)*(1+Inputs!$B$5)),IF(MONTH($A2)>=Inputs!#REF!,Inputs!$B$2*(1+Inputs!$B$4)*(1+Inputs!$B$5)*(1+Inputs!$B$6)*(1+Inputs!$B$7),Inputs!$B$2*(1+Inputs!$B$4)*(1+Inputs!$B$5)*(1+Inputs!$B$6)))))))/12)*(MIN(Inputs!$B$17,Inputs!$B$18)*(1+Inputs!$B$19)+Inputs!$B$17*Inputs!$B$20),0) -> 0 | H2: =SUM(B2:G2) -> 7166.6667 | I2: =$H2-J2-K2 -> 6470 | J2: =_xlfn.SINGLE(_xlfn.LET(_xlpm.d, $A2, _xlpm.ys, YEAR(_xlfn.SINGLE(_xlpm.d)) - IF(MONTH(_xlfn.SINGLE(_xlpm.d)) < UK_TaxYear_Start_Month, 1, 0), _xlpm.start, DATE(_xlfn.SINGLE(_xlpm.ys), UK_TaxYear_Start_Month, 1), _xlpm.m, DATEDIF(_xlfn.SINGLE(_xlpm.start), _xlfn.SINGLE(_xlpm.d), "m") + 1, _xlpm.cum, SUMIFS($H$2:$H$54, $A$2:$A$54, ">=" & _xlfn.SINGLE(_xlpm.start), $A$2:$A$54, "<=" & _xlfn.SINGLE(_xlpm.d)), _xlpm.pa, UK_Personal_Allowance_Annual / 12 * _xlfn.SINGLE(_xlpm.m), _xlpm.br, (UK_Basic_Band_Upper_Annual - UK_Personal_Allowance_Annual) / 12 * _xlfn.SINGLE(_xlpm.m), _xlpm.hr, (UK_Higher_Band_Upper_Annual - UK_Basic_Band_Upper_Annual) / 12 * _xlfn.SINGLE(_xlpm.m), _xlpm.taxable, MAX(0, _xlfn.SINGLE(_xlpm.cum) - _xlfn.SINGLE(_xlpm.pa)), _xlpm.tax_to_date, UK_Basic_Rate * MIN(_xlpm.taxable, _xlpm.br) + UK_Higher_Rate * MIN(MAX(_xlfn.SINGLE(_xlpm.taxable) - _xlfn.SINGLE(_xlpm.br), 0), _xlpm.hr) + UK_Additional_Rate * MAX(_xlfn.SINGLE(_xlpm.taxable) - _xlfn.SINGLE(_xlpm.br) - _xlfn.SINGLE(_xlpm.hr), 0), _xlpm.prior, SUMIFS($J$2:$J$54, $A$2:$A$54, ">=" & _xlfn.SINGLE(_xlpm.start), $A$2:$A$54, "<" & _xlfn.SINGLE(_xlpm.d)), MAX(0, _xlfn.SINGLE(_xlpm.tax_to_date) - _xlfn.SINGLE(_xlpm.prior)))) -> 385.83333 | K2: =_xlfn.SINGLE(_xlfn.LET(_xlpm.g, $H2, _xlpm.pt, UK_NI_PT_Monthly, _xlpm.uel, UK_NI_UEL_Monthly, IF(_xlfn.SINGLE(_xlpm.g) <= _xlfn.SINGLE(_xlpm.pt), 0, UK_NI_Main_Rate * MIN(_xlfn.SINGLE(_xlpm.g) - _xlfn.SINGLE(_xlpm.pt), _xlfn.SINGLE(_xlpm.uel) - _xlfn.SINGLE(_xlpm.pt)) + UK_NI_Upper_Rate * MAX(_xlfn.SINGLE(_xlpm.g) - _xlfn.SINGLE(_xlpm.uel), 0)))) -> 310.83333 | L2: =IF($A2<DATE(2026,10,1),Bonus_Pct_Aug2026_to_Sep2026,IF($A2<DATE(2027,10,1),Bonus_Pct_Oct2026_to_Sep2027,IF($A2<DATE(2028,10,1),Bonus_Pct_Oct2027_to_Sep2028,IF($A2<DATE(2029,10,1),Bonus_Pct_Oct2028_to_Sep2029,Bonus_Pct_Oct2029_onwards)))) -> 0.08
A3: 46266 | B3: =(IF(YEAR($A3)=2026,Base_Annual_Salary_GBP,IF(YEAR($A3)=2027,Base_Annual_Salary_GBP*(IF(MONTH($A3)>=4,(1+Raise_Pct_Apr2027),1)*IF(MONTH($A3)>=10,(1+Raise_Pct_Nov2027),1)),IF(YEAR($A3)=2028,Base_Annual_Salary_GBP*((1+Raise_Pct_Apr2027)*(1+Raise_Pct_Nov2027))*(IF(MONTH($A3)>=4,(1+Raise_Pct_Apr2028),1)*IF(MONTH($A3)>=10,(1+Raise_Pct_Nov2028),1)),IF(YEAR($A3)=2029,Base_Annual_Salary_GBP*((1+Raise_Pct_Apr2027)*(1+Raise_Pct_Nov2027)*(1+Raise_Pct_Apr2028)*(1+Raise_Pct_Nov2028))*(IF(MONTH($A3)>=4,(1+Raise_Pct_Apr2029),1)*IF(MONTH($A3)>=10,(1+Raise_Pct_Nov2029),1)),Base_Annual_Salary_GBP*((1+Raise_Pct_Apr2027)*(1+Raise_Pct_Nov2027)*(1+Raise_Pct_Apr2028)*(1+Raise_Pct_Nov2028)*(1+Raise_Pct_Apr2029)*(1+Raise_Pct_Nov2029))*(IF(MONTH($A3)>=4,(1+Raise_Pct_Apr2030),1)*IF(MONTH($A3)>=10,(1+Raise_Pct_Nov2030),1)))))))/12 -> 4166.6667 | C3: =IF(MONTH($A3)=11,((IF(DATE(YEAR($A3),4,1)<DATE(2026,10,1),Bonus_Pct_Aug2026_to_Sep2026,IF(DATE(YEAR($A3),4,1)<DATE(2027,10,1),Bonus_Pct_Oct2026_to_Sep2027,IF(DATE(YEAR($A3),4,1)<DATE(2028,10,1),Bonus_Pct_Oct2027_to_Sep2028,IF(DATE(YEAR($A3),4,1)<DATE(2029,10,1),Bonus_Pct_Oct2028_to_Sep2029,Bonus_Pct_Oct2029_onwards)))))/2)*($B3*12) / (1 + IF(YEAR($A3)=2027,Raise_Pct_Nov2027,IF(YEAR($A3)=2028,Raise_Pct_Nov2028,IF(YEAR($A3)=2029,Raise_Pct_Nov2029,IF(YEAR($A3)=2030,Raise_Pct_Nov2030,0))))) * IF(YEAR($A3)=2026,2/6,1),IF(MONTH($A3)=5,((IF(DATE(YEAR($A3)-1,10,1)<DATE(2026,10,1),Bonus_Pct_Aug2026_to_Sep2026,IF(DATE(YEAR($A3)-1,10,1)<DATE(2027,10,1),Bonus_Pct_Oct2026_to_Sep2027,IF(DATE(YEAR($A3)-1,10,1)<DATE(2028,10,1),Bonus_Pct_Oct2027_to_Sep2028,IF(DATE(YEAR($A3)-1,10,1)<DATE(2029,10,1),Bonus_Pct_Oct2028_to_Sep2029,Bonus_Pct_Oct2029_onwards)))))/2)*($B3*12) / (1 + IF(YEAR($A3)=2027,Raise_Pct_Apr2027,IF(YEAR($A3)=2028,Raise_Pct_Apr2028,IF(YEAR($A3)=2029,Raise_Pct_Apr2029,IF(YEAR($A3)=2030,Raise_Pct_Apr2030,0))))),0)) -> 0 | D3: =IF(OR($A3=DATE(2027,9,1),$A3=EDATE(DATE(2027,9,1),12),$A3=EDATE(DATE(2027,9,1),24)),(New_Hire_Stock_Grant_USD/3)/FX_USD_per_GBP*(1+IF(YEAR($A3)=2027,Inputs!$B$56,IF(YEAR($A3)=2028,Inputs!$B$57,IF(YEAR($A3)=2029,Inputs!$B$58,0)))),0)+IF(OR($A3=DATE(2028,11,1),$A3=DATE(2029,11,1),$A3=DATE(2030,11,1)),(RSU_Grant_Nov2027_USD/3)/FX_USD_per_GBP*(1+RSU_Price_Change_Pct)^(YEAR($A3)-2028),0)+IF(OR($A3=DATE(2029,11,1),$A3=DATE(2030,11,1)),(RSU_Grant_Nov2028_USD/3)/FX_USD_per_GBP*(1+RSU_Price_Change_Pct)^(YEAR($A3)-2029),0)+IF($A3=DATE(2030,11,1),(RSU_Grant_Nov2029_USD/3)/FX_USD_per_GBP*(1+RSU_Price_Change_Pct)^(YEAR($A3)-2030),0) -> 0 | E3: =IF($A3=EDATE(DATE(2026,8,1),Inputs!$B$9),Inputs!$B$8,0) -> 0 | F3: =IF($A3=EDATE(DATE(2026,8,1),Inputs!$B$11),Inputs!$B$10,0) -> 0 | G3: =IF(Inputs!$B$16=1,((IF(YEAR($A3)=2026,Inputs!$B$2,IF(YEAR($A3)=2027,IF(MONTH($A3)>=Inputs!#REF!,Inputs!$B$2*(1+Inputs!$B$4),Inputs!$B$2),IF(YEAR($A3)=2028,IF(MONTH($A3)>=Inputs!#REF!,Inputs!$B$2*(1+Inputs!$B$4)*(1+Inputs!$B$5),Inputs!$B$2*(1+Inputs!$B$4)),IF(YEAR($A3)=2029,IF(MONTH($A3)>=Inputs!#REF!,Inputs!$B$2*(1+Inputs!$B$4)*(1+Inputs!$B$5)*(1+Inputs!$B$6),Inputs!$B$2*(1+Inputs!$B$4)*(1+Inputs!$B$5)),IF(MONTH($A3)>=Inputs!#REF!,Inputs!$B$2*(1+Inputs!$B$4)*(1+Inputs!$B$5)*(1+Inputs!$B$6)*(1+Inputs!$B$7),Inputs!$B$2*(1+Inputs!$B$4)*(1+Inputs!$B$5)*(1+Inputs!$B$6)))))))/12)*(MIN(Inputs!$B$17,Inputs!$B$18)*(1+Inputs!$B$19)+Inputs!$B$17*Inputs!$B$20),0) -> 0 | H3: =SUM(B3:G3) -> 4166.6667 | I3: =$H3-J3-K3 -> 3293.34 | J3: =_xlfn.SINGLE(_xlfn.LET(_xlpm.d, $A3, _xlpm.ys, YEAR(_xlfn.SINGLE(_xlpm.d)) - IF(MONTH(_xlfn.SINGLE(_xlpm.d)) < UK_TaxYear_Start_Month, 1, 0), _xlpm.start, DATE(_xlfn.SINGLE(_xlpm.ys), UK_TaxYear_Start_Month, 1), _xlpm.m, DATEDIF(_xlfn.SINGLE(_xlpm.start), _xlfn.SINGLE(_xlpm.d), "m") + 1, _xlpm.cum, SUMIFS($H$2:$H$54, $A$2:$A$54, ">=" & _xlfn.SINGLE(_xlpm.start), $A$2:$A$54, "<=" & _xlfn.SINGLE(_xlpm.d)), _xlpm.pa, UK_Personal_Allowance_Annual / 12 * _xlfn.SINGLE(_xlpm.m), _xlpm.br, (UK_Basic_Band_Upper_Annual - UK_Personal_Allowance_Annual) / 12 * _xlfn.SINGLE(_xlpm.m), _xlpm.hr, (UK_Higher_Band_Upper_Annual - UK_Basic_Band_Upper_Annual) / 12 * _xlfn.SINGLE(_xlpm.m), _xlpm.taxable, MAX(0, _xlfn.SINGLE(_xlpm.cum) - _xlfn.SINGLE(_xlpm.pa)), _xlpm.tax_to_date, UK_Basic_Rate * MIN(_xlpm.taxable, _xlpm.br) + UK_Higher_Rate * MIN(MAX(_xlfn.SINGLE(_xlpm.taxable) - _xlfn.SINGLE(_xlpm.br), 0), _xlpm.hr) + UK_Additional_Rate * MAX(_xlfn.SINGLE(_xlpm.taxable) - _xlfn.SINGLE(_xlpm.br) - _xlfn.SINGLE(_xlpm.hr), 0), _xlpm.prior, SUMIFS($J$2:$J$54, $A$2:$A$54, ">=" & _xlfn.SINGLE(_xlpm.start), $A$2:$A$54, "<" & _xlfn.SINGLE(_xlpm.d)), MAX(0, _xlfn.SINGLE(_xlpm.tax_to_date) - _xlfn.SINGLE(_xlpm.prior)))) -> 623.83333 | K3: =_xlfn.SINGLE(_xlfn.LET(_xlpm.g, $H3, _xlpm.pt, UK_NI_PT_Monthly, _xlpm.uel, UK_NI_UEL_Monthly, IF(_xlfn.SINGLE(_xlpm.g) <= _xlfn.SINGLE(_xlpm.pt), 0, UK_NI_Main_Rate * MIN(_xlfn.SINGLE(_xlpm.g) - _xlfn.SINGLE(_xlpm.pt), _xlfn.SINGLE(_xlpm.uel) - _xlfn.SINGLE(_xlpm.pt)) + UK_NI_Upper_Rate * MAX(_xlfn.SINGLE(_xlpm.g) - _xlfn.SINGLE(_xlpm.uel), 0)))) -> 249.49333 | L3: =IF($A3<DATE(2026,10,1),Bonus_Pct_Aug2026_to_Sep2026,IF($A3<DATE(2027,10,1),Bonus_Pct_Oct2026_to_Sep2027,IF($A3<DATE(2028,10,1),Bonus_Pct_Oct2027_to_Sep2028,IF($A3<DATE(2029,10,1),Bonus_Pct_Oct2028_to_Sep2029,Bonus_Pct_Oct2029_onwards)))) -> 0.08
A4: 46296 | B4: =(IF(YEAR($A4)=2026,Base_Annual_Salary_GBP,IF(YEAR($A4)=2027,Base_Annual_Salary_GBP*(IF(MONTH($A4)>=4,(1+Raise_Pct_Apr2027),1)*IF(MONTH($A4)>=10,(1+Raise_Pct_Nov2027),1)),IF(YEAR($A4)=2028,Base_Annual_Salary_GBP*((1+Raise_Pct_Apr2027)*(1+Raise_Pct_Nov2027))*(IF(MONTH($A4)>=4,(1+Raise_Pct_Apr2028),1)*IF(MONTH($A4)>=10,(1+Raise_Pct_Nov2028),1)),IF(YEAR($A4)=2029,Base_Annual_Salary_GBP*((1+Raise_Pct_Apr2027)*(1+Raise_Pct_Nov2027)*(1+Raise_Pct_Apr2028)*(1+Raise_Pct_Nov2028))*(IF(MONTH($A4)>=4,(1+Raise_Pct_Apr2029),1)*IF(MONTH($A4)>=10,(1+Raise_Pct_Nov2029),1)),Base_Annual_Salary_GBP*((1+Raise_Pct_Apr2027)*(1+Raise_Pct_Nov2027)*(1+Raise_Pct_Apr2028)*(1+Raise_Pct_Nov2028)*(1+Raise_Pct_Apr2029)*(1+Raise_Pct_Nov2029))*(IF(MONTH($A4)>=4,(1+Raise_Pct_Apr2030),1)*IF(MONTH($A4)>=10,(1+Raise_Pct_Nov2030),1)))))))/12 -> 4166.6667 | C4: =IF(MONTH($A4)=11,((IF(DATE(YEAR($A4),4,1)<DATE(2026,10,1),Bonus_Pct_Aug2026_to_Sep2026,IF(DATE(YEAR($A4),4,1)<DATE(2027,10,1),Bonus_Pct_Oct2026_to_Sep2027,IF(DATE(YEAR($A4),4,1)<DATE(2028,10,1),Bonus_Pct_Oct2027_to_Sep2028,IF(DATE(YEAR($A4),4,1)<DATE(2029,10,1),Bonus_Pct_Oct2028_to_Sep2029,Bonus_Pct_Oct2029_onwards)))))/2)*($B4*12) / (1 + IF(YEAR($A4)=2027,Raise_Pct_Nov2027,IF(YEAR($A4)=2028,Raise_Pct_Nov2028,IF(YEAR($A4)=2029,Raise_Pct_Nov2029,IF(YEAR($A4)=2030,Raise_Pct_Nov2030,0))))) * IF(YEAR($A4)=2026,2/6,1),IF(MONTH($A4)=5,((IF(DATE(YEAR($A4)-1,10,1)<DATE(2026,10,1),Bonus_Pct_Aug2026_to_Sep2026,IF(DATE(YEAR($A4)-1,10,1)<DATE(2027,10,1),Bonus_Pct_Oct2026_to_Sep2027,IF(DATE(YEAR($A4)-1,10,1)<DATE(2028,10,1),Bonus_Pct_Oct2027_to_Sep2028,IF(DATE(YEAR($A4)-1,10,1)<DATE(2029,10,1),Bonus_Pct_Oct2028_to_Sep2029,Bonus_Pct_Oct2029_onwards)))))/2)*($B4*12) / (1 + IF(YEAR($A4)=2027,Raise_Pct_Apr2027,IF(YEAR($A4)=2028,Raise_Pct_Apr2028,IF(YEAR($A4)=2029,Raise_Pct_Apr2029,IF(YEAR($A4)=2030,Raise_Pct_Apr2030,0))))),0)) -> 0 | D4: =IF(OR($A4=DATE(2027,9,1),$A4=EDATE(DATE(2027,9,1),12),$A4=EDATE(DATE(2027,9,1),24)),(New_Hire_Stock_Grant_USD/3)/FX_USD_per_GBP*(1+IF(YEAR($A4)=2027,Inputs!$B$56,IF(YEAR($A4)=2028,Inputs!$B$57,IF(YEAR($A4)=2029,Inputs!$B$58,0)))),0)+IF(OR($A4=DATE(2028,11,1),$A4=DATE(2029,11,1),$A4=DATE(2030,11,1)),(RSU_Grant_Nov2027_USD/3)/FX_USD_per_GBP*(1+RSU_Price_Change_Pct)^(YEAR($A4)-2028),0)+IF(OR($A4=DATE(2029,11,1),$A4=DATE(2030,11,1)),(RSU_Grant_Nov2028_USD/3)/FX_USD_per_GBP*(1+RSU_Price_Change_Pct)^(YEAR($A4)-2029),0)+IF($A4=DATE(2030,11,1),(RSU_Grant_Nov2029_USD/3)/FX_USD_per_GBP*(1+RSU_Price_Change_Pct)^(YEAR($A4)-2030),0) -> 0 | E4: =IF($A4=EDATE(DATE(2026,8,1),Inputs!$B$9),Inputs!$B$8,0) -> 0 | F4: =IF($A4=EDATE(DATE(2026,8,1),Inputs!$B$11),Inputs!$B$10,0) -> 0 | G4: =IF(Inputs!$B$16=1,((IF(YEAR($A4)=2026,Inputs!$B$2,IF(YEAR($A4)=2027,IF(MONTH($A4)>=Inputs!#REF!,Inputs!$B$2*(1+Inputs!$B$4),Inputs!$B$2),IF(YEAR($A4)=2028,IF(MONTH($A4)>=Inputs!#REF!,Inputs!$B$2*(1+Inputs!$B$4)*(1+Inputs!$B$5),Inputs!$B$2*(1+Inputs!$B$4)),IF(YEAR($A4)=2029,IF(MONTH($A4)>=Inputs!#REF!,Inputs!$B$2*(1+Inputs!$B$4)*(1+Inputs!$B$5)*(1+Inputs!$B$6),Inputs!$B$2*(1+Inputs!$B$4)*(1+Inputs!$B$5)),IF(MONTH($A4)>=Inputs!#REF!,Inputs!$B$2*(1+Inputs!$B$4)*(1+Inputs!$B$5)*(1+Inputs!$B$6)*(1+Inputs!$B$7),Inputs!$B$2*(1+Inputs!$B$4)*(1+Inputs!$B$5)*(1+Inputs!$B$6)))))))/12)*(MIN(Inputs!$B$17,Inputs!$B$18)*(1+Inputs!$B$19)+Inputs!$B$17*Inputs!$B$20),0) -> 0 | H4: =SUM(B4:G4) -> 4166.6667 | I4: =$H4-J4-K4 -> 3293.34 | J4: =_xlfn.SINGLE(_xlfn.LET(_xlpm.d, $A4, _xlpm.ys, YEAR(_xlfn.SINGLE(_xlpm.d)) - IF(MONTH(_xlfn.SINGLE(_xlpm.d)) < UK_TaxYear_Start_Month, 1, 0), _xlpm.start, DATE(_xlfn.SINGLE(_xlpm.ys), UK_TaxYear_Start_Month, 1), _xlpm.m, DATEDIF(_xlfn.SINGLE(_xlpm.start), _xlfn.SINGLE(_xlpm.d), "m") + 1, _xlpm.cum, SUMIFS($H$2:$H$54, $A$2:$A$54, ">=" & _xlfn.SINGLE(_xlpm.start), $A$2:$A$54, "<=" & _xlfn.SINGLE(_xlpm.d)), _xlpm.pa, UK_Personal_Allowance_Annual / 12 * _xlfn.SINGLE(_xlpm.m), _xlpm.br, (UK_Basic_Band_Upper_Annual - UK_Personal_Allowance_Annual) / 12 * _xlfn.SINGLE(_xlpm.m), _xlpm.hr, (UK_Higher_Band_Upper_Annual - UK_Basic_Band_Upper_Annual) / 12 * _xlfn.SINGLE(_xlpm.m), _xlpm.taxable, MAX(0, _xlfn.SINGLE(_xlpm.cum) - _xlfn.SINGLE(_xlpm.pa)), _xlpm.tax_to_date, UK_Basic_Rate * MIN(_xlpm.taxable, _xlpm.br) + UK_Higher_Rate * MIN(MAX(_xlfn.SINGLE(_xlpm.taxable) - _xlfn.SINGLE(_xlpm.br), 0), _xlpm.hr) + UK_Additional_Rate * MAX(_xlfn.SINGLE(_xlpm.taxable) - _xlfn.SINGLE(_xlpm.br) - _xlfn.SINGLE(_xlpm.hr), 0), _xlpm.prior, SUMIFS($J$2:$J$54, $A$2:$A$54, ">=" & _xlfn.SINGLE(_xlpm.start), $A$2:$A$54, "<" & _xlfn.SINGLE(_xlpm.d)), MAX(0, _xlfn.SINGLE(_xlpm.tax_to_date) - _xlfn.SINGLE(_xlpm.prior)))) -> 623.83333 | K4: =_xlfn.SINGLE(_xlfn.LET(_xlpm.g, $H4, _xlpm.pt, UK_NI_PT_Monthly, _xlpm.uel, UK_NI_UEL_Monthly, IF(_xlfn.SINGLE(_xlpm.g) <= _xlfn.SINGLE(_xlpm.pt), 0, UK_NI_Main_Rate * MIN(_xlfn.SINGLE(_xlpm.g) - _xlfn.SINGLE(_xlpm.pt), _xlfn.SINGLE(_xlpm.uel) - _xlfn.SINGLE(_xlpm.pt)) + UK_NI_Upper_Rate * MAX(_xlfn.SINGLE(_xlpm.g) - _xlfn.SINGLE(_xlpm.uel), 0)))) -> 249.49333 | L4: =IF($A4<DATE(2026,10,1),Bonus_Pct_Aug2026_to_Sep2026,IF($A4<DATE(2027,10,1),Bonus_Pct_Oct2026_to_Sep2027,IF($A4<DATE(2028,10,1),Bonus_Pct_Oct2027_to_Sep2028,IF($A4<DATE(2029,10,1),Bonus_Pct_Oct2028_to_Sep2029,Bonus_Pct_Oct2029_onwards)))) -> 0.08
A5: 46327 | B5: =(IF(YEAR($A5)=2026,Base_Annual_Salary_GBP,IF(YEAR($A5)=2027,Base_Annual_Salary_GBP*(IF(MONTH($A5)>=4,(1+Raise_Pct_Apr2027),1)*IF(MONTH($A5)>=10,(1+Raise_Pct_Nov2027),1)),IF(YEAR($A5)=2028,Base_Annual_Salary_GBP*((1+Raise_Pct_Apr2027)*(1+Raise_Pct_Nov2027))*(IF(MONTH($A5)>=4,(1+Raise_Pct_Apr2028),1)*IF(MONTH($A5)>=10,(1+Raise_Pct_Nov2028),1)),IF(YEAR($A5)=2029,Base_Annual_Salary_GBP*((1+Raise_Pct_Apr2027)*(1+Raise_Pct_Nov2027)*(1+Raise_Pct_Apr2028)*(1+Raise_Pct_Nov2028))*(IF(MONTH($A5)>=4,(1+Raise_Pct_Apr2029),1)*IF(MONTH($A5)>=10,(1+Raise_Pct_Nov2029),1)),Base_Annual_Salary_GBP*((1+Raise_Pct_Apr2027)*(1+Raise_Pct_Nov2027)*(1+Raise_Pct_Apr2028)*(1+Raise_Pct_Nov2028)*(1+Raise_Pct_Apr2029)*(1+Raise_Pct_Nov2029))*(IF(MONTH($A5)>=4,(1+Raise_Pct_Apr2030),1)*IF(MONTH($A5)>=10,(1+Raise_Pct_Nov2030),1)))))))/12 -> 4166.6667 | C5: =IF(MONTH($A5)=11,((IF(DATE(YEAR($A5),4,1)<DATE(2026,10,1),Bonus_Pct_Aug2026_to_Sep2026,IF(DATE(YEAR($A5),4,1)<DATE(2027,10,1),Bonus_Pct_Oct2026_to_Sep2027,IF(DATE(YEAR($A5),4,1)<DATE(2028,10,1),Bonus_Pct_Oct2027_to_Sep2028,IF(DATE(YEAR($A5),4,1)<DATE(2029,10,1),Bonus_Pct_Oct2028_to_Sep2029,Bonus_Pct_Oct2029_onwards)))))/2)*($B5*12) / (1 + IF(YEAR($A5)=2027,Raise_Pct_Nov2027,IF(YEAR($A5)=2028,Raise_Pct_Nov2028,IF(YEAR($A5)=2029,Raise_Pct_Nov2029,IF(YEAR($A5)=2030,Raise_Pct_Nov2030,0))))) * IF(YEAR($A5)=2026,2/6,1),IF(MONTH($A5)=5,((IF(DATE(YEAR($A5)-1,10,1)<DATE(2026,10,1),Bonus_Pct_Aug2026_to_Sep2026,IF(DATE(YEAR($A5)-1,10,1)<DATE(2027,10,1),Bonus_Pct_Oct2026_to_Sep2027,IF(DATE(YEAR($A5)-1,10,1)<DATE(2028,10,1),Bonus_Pct_Oct2027_to_Sep2028,IF(DATE(YEAR($A5)-1,10,1)<DATE(2029,10,1),Bonus_Pct_Oct2028_to_Sep2029,Bonus_Pct_Oct2029_onwards)))))/2)*($B5*12) / (1 + IF(YEAR($A5)=2027,Raise_Pct_Apr2027,IF(YEAR($A5)=2028,Raise_Pct_Apr2028,IF(YEAR($A5)=2029,Raise_Pct_Apr2029,IF(YEAR($A5)=2030,Raise_Pct_Apr2030,0))))),0)) -> 666.66667 | D5: =IF(OR($A5=DATE(2027,9,1),$A5=EDATE(DATE(2027,9,1),12),$A5=EDATE(DATE(2027,9,1),24)),(New_Hire_Stock_Grant_USD/3)/FX_USD_per_GBP*(1+IF(YEAR($A5)=2027,Inputs!$B$56,IF(YEAR($A5)=2028,Inputs!$B$57,IF(YEAR($A5)=2029,Inputs!$B$58,0)))),0)+IF(OR($A5=DATE(2028,11,1),$A5=DATE(2029,11,1),$A5=DATE(2030,11,1)),(RSU_Grant_Nov2027_USD/3)/FX_USD_per_GBP*(1+RSU_Price_Change_Pct)^(YEAR($A5)-2028),0)+IF(OR($A5=DATE(2029,11,1),$A5=DATE(2030,11,1)),(RSU_Grant_Nov2028_USD/3)/FX_USD_per_GBP*(1+RSU_Price_Change_Pct)^(YEAR($A5)-2029),0)+IF($A5=DATE(2030,11,1),(RSU_Grant_Nov2029_USD/3)/FX_USD_per_GBP*(1+RSU_Price_Change_Pct)^(YEAR($A5)-2030),0) -> 0 | E5: =IF($A5=EDATE(DATE(2026,8,1),Inputs!$B$9),Inputs!$B$8,0) -> 0 | F5: =IF($A5=EDATE(DATE(2026,8,1),Inputs!$B$11),Inputs!$B$10,0) -> 0 | G5: =IF(Inputs!$B$16=1,((IF(YEAR($A5)=2026,Inputs!$B$2,IF(YEAR($A5)=2027,IF(MONTH($A5)>=Inputs!#REF!,Inputs!$B$2*(1+Inputs!$B$4),Inputs!$B$2),IF(YEAR($A5)=2028,IF(MONTH($A5)>=Inputs!#REF!,Inputs!$B$2*(1+Inputs!$B$4)*(1+Inputs!$B$5),Inputs!$B$2*(1+Inputs!$B$4)),IF(YEAR($A5)=2029,IF(MONTH($A5)>=Inputs!#REF!,Inputs!$B$2*(1+Inputs!$B$4)*(1+Inputs!$B$5)*(1+Inputs!$B$6),Inputs!$B$2*(1+Inputs!$B$4)*(1+Inputs!$B$5)),IF(MONTH($A5)>=Inputs!#REF!,Inputs!$B$2*(1+Inputs!$B$4)*(1+Inputs!$B$5)*(1+Inputs!$B$6)*(1+Inputs!$B$7),Inputs!$B$2*(1+Inputs!$B$4)*(1+Inputs!$B$5)*(1+Inputs!$B$6)))))))/12)*(MIN(Inputs!$B$17,Inputs!$B$18)*(1+Inputs!$B$19)+Inputs!$B$17*Inputs!$B$20),0) -> 0 | H5: =SUM(B5:G5) -> 4833.3333 | I5: =$H5-J5-K5 -> 3812 | J5: =_xlfn.SINGLE(_xlfn.LET(_xlpm.d, $A5, _xlpm.ys, YEAR(_xlfn.SINGLE(_xlpm.d)) - IF(MONTH(_xlfn.SINGLE(_xlpm.d)) < UK_TaxYear_Start_Month, 1, 0), _xlpm.start, DATE(_xlfn.SINGLE(_xlpm.ys), UK_TaxYear_Start_Month, 1), _xlpm.m, DATEDIF(_xlfn.SINGLE(_xlpm.start), _xlfn.SINGLE(_xlpm.d), "m") + 1, _xlpm.cum, SUMIFS($H$2:$H$54, $A$2:$A$54, ">=" & _xlfn.SINGLE(_xlpm.start), $A$2:$A$54, "<=" & _xlfn.SINGLE(_xlpm.d)), _xlpm.pa, UK_Personal_Allowance_Annual / 12 * _xlfn.SINGLE(_xlpm.m), _xlpm.br, (UK_Basic_Band_Upper_Annual - UK_Personal_Allowance_Annual) / 12 * _xlfn.SINGLE(_xlpm.m), _xlpm.hr, (UK_Higher_Band_Upper_Annual - UK_Basic_Band_Upper_Annual) / 12 * _xlfn.SINGLE(_xlpm.m), _xlpm.taxable, MAX(0, _xlfn.SINGLE(_xlpm.cum) - _xlfn.SINGLE(_xlpm.pa)), _xlpm.tax_to_date, UK_Basic_Rate * MIN(_xlpm.taxable, _xlpm.br) + UK_Higher_Rate * MIN(MAX(_xlfn.SINGLE(_xlpm.taxable) - _xlfn.SINGLE(_xlpm.br), 0), _xlpm.hr) + UK_Additional_Rate * MAX(_xlfn.SINGLE(_xlpm.taxable) - _xlfn.SINGLE(_xlpm.br) - _xlfn.SINGLE(_xlpm.hr), 0), _xlpm.prior, SUMIFS($J$2:$J$54, $A$2:$A$54, ">=" & _xlfn.SINGLE(_xlpm.start), $A$2:$A$54, "<" & _xlfn.SINGLE(_xlpm.d)), MAX(0, _xlfn.SINGLE(_xlpm.tax_to_date) - _xlfn.SINGLE(_xlpm.prior)))) -> 757.16667 | K5: =_xlfn.SINGLE(_xlfn.LET(_xlpm.g, $H5, _xlpm.pt, UK_NI_PT_Monthly, _xlpm.uel, UK_NI_UEL_Monthly, IF(_xlfn.SINGLE(_xlpm.g) <= _xlfn.SINGLE(_xlpm.pt), 0, UK_NI_Main_Rate * MIN(_xlfn.SINGLE(_xlpm.g) - _xlfn.SINGLE(_xlpm.pt), _xlfn.SINGLE(_xlpm.uel) - _xlfn.SINGLE(_xlpm.pt)) + UK_NI_Upper_Rate * MAX(_xlfn.SINGLE(_xlpm.g) - _xlfn.SINGLE(_xlpm.uel), 0)))) -> 264.16667 | L5: =IF($A5<DATE(2026,10,1),Bonus_Pct_Aug2026_to_Sep2026,IF($A5<DATE(2027,10,1),Bonus_Pct_Oct2026_to_Sep2027,IF($A5<DATE(2028,10,1),Bonus_Pct_Oct2027_to_Sep2028,IF($A5<DATE(2029,10,1),Bonus_Pct_Oct2028_to_Sep2029,Bonus_Pct_Oct2029_onwards)))) -> 0.08
A6: 46357 | B6: =(IF(YEAR($A6)=2026,Base_Annual_Salary_GBP,IF(YEAR($A6)=2027,Base_Annual_Salary_GBP*(IF(MONTH($A6)>=4,(1+Raise_Pct_Apr2027),1)*IF(MONTH($A6)>=10,(1+Raise_Pct_Nov2027),1)),IF(YEAR($A6)=2028,Base_Annual_Salary_GBP*((1+Raise_Pct_Apr2027)*(1+Raise_Pct_Nov2027))*(IF(MONTH($A6)>=4,(1+Raise_Pct_Apr2028),1)*IF(MONTH($A6)>=10,(1+Raise_Pct_Nov2028),1)),IF(YEAR($A6)=2029,Base_Annual_Salary_GBP*((1+Raise_Pct_Apr2027)*(1+Raise_Pct_Nov2027)*(1+Raise_Pct_Apr2028)*(1+Raise_Pct_Nov2028))*(IF(MONTH($A6)>=4,(1+Raise_Pct_Apr2029),1)*IF(MONTH($A6)>=10,(1+Raise_Pct_Nov2029),1)),Base_Annual_Salary_GBP*((1+Raise_Pct_Apr2027)*(1+Raise_Pct_Nov2027)*(1+Raise_Pct_Apr2028)*(1+Raise_Pct_Nov2028)*(1+Raise_Pct_Apr2029)*(1+Raise_Pct_Nov2029))*(IF(MONTH($A6)>=4,(1+Raise_Pct_Apr2030),1)*IF(MONTH($A6)>=10,(1+Raise_Pct_Nov2030),1)))))))/12 -> 4166.6667 | C6: =IF(MONTH($A6)=11,((IF(DATE(YEAR($A6),4,1)<DATE(2026,10,1),Bonus_Pct_Aug2026_to_Sep2026,IF(DATE(YEAR($A6),4,1)<DATE(2027,10,1),Bonus_Pct_Oct2026_to_Sep2027,IF(DATE(YEAR($A6),4,1)<DATE(2028,10,1),Bonus_Pct_Oct2027_to_Sep2028,IF(DATE(YEAR($A6),4,1)<DATE(2029,10,1),Bonus_Pct_Oct2028_to_Sep2029,Bonus_Pct_Oct2029_onwards)))))/2)*($B6*12) / (1 + IF(YEAR($A6)=2027,Raise_Pct_Nov2027,IF(YEAR($A6)=2028,Raise_Pct_Nov2028,IF(YEAR($A6)=2029,Raise_Pct_Nov2029,IF(YEAR($A6)=2030,Raise_Pct_Nov2030,0))))) * IF(YEAR($A6)=2026,2/6,1),IF(MONTH($A6)=5,((IF(DATE(YEAR($A6)-1,10,1)<DATE(2026,10,1),Bonus_Pct_Aug2026_to_Sep2026,IF(DATE(YEAR($A6)-1,10,1)<DATE(2027,10,1),Bonus_Pct_Oct2026_to_Sep2027,IF(DATE(YEAR($A6)-1,10,1)<DATE(2028,10,1),Bonus_Pct_Oct2027_to_Sep2028,IF(DATE(YEAR($A6)-1,10,1)<DATE(2029,10,1),Bonus_Pct_Oct2028_to_Sep2029,Bonus_Pct_Oct2029_onwards)))))/2)*($B6*12) / (1 + IF(YEAR($A6)=2027,Raise_Pct_Apr2027,IF(YEAR($A6)=2028,Raise_Pct_Apr2028,IF(YEAR($A6)=2029,Raise_Pct_Apr2029,IF(YEAR($A6)=2030,Raise_Pct_Apr2030,0))))),0)) -> 0 | D6: =IF(OR($A6=DATE(2027,9,1),$A6=EDATE(DATE(2027,9,1),12),$A6=EDATE(DATE(2027,9,1),24)),(New_Hire_Stock_Grant_USD/3)/FX_USD_per_GBP*(1+IF(YEAR($A6)=2027,Inputs!$B$56,IF(YEAR($A6)=2028,Inputs!$B$57,IF(YEAR($A6)=2029,Inputs!$B$58,0)))),0)+IF(OR($A6=DATE(2028,11,1),$A6=DATE(2029,11,1),$A6=DATE(2030,11,1)),(RSU_Grant_Nov2027_USD/3)/FX_USD_per_GBP*(1+RSU_Price_Change_Pct)^(YEAR($A6)-2028),0)+IF(OR($A6=DATE(2029,11,1),$A6=DATE(2030,11,1)),(RSU_Grant_Nov2028_USD/3)/FX_USD_per_GBP*(1+RSU_Price_Change_Pct)^(YEAR($A6)-2029),0)+IF($A6=DATE(2030,11,1),(RSU_Grant_Nov2029_USD/3)/FX_USD_per_GBP*(1+RSU_Price_Change_Pct)^(YEAR($A6)-2030),0) -> 0 | E6: =IF($A6=EDATE(DATE(2026,8,1),Inputs!$B$9),Inputs!$B$8,0) -> 0 | F6: =IF($A6=EDATE(DATE(2026,8,1),Inputs!$B$11),Inputs!$B$10,0) -> 0 | G6: =IF(Inputs!$B$16=1,((IF(YEAR($A6)=2026,Inputs!$B$2,IF(YEAR($A6)=2027,IF(MONTH($A6)>=Inputs!#REF!,Inputs!$B$2*(1+Inputs!$B$4),Inputs!$B$2),IF(YEAR($A6)=2028,IF(MONTH($A6)>=Inputs!#REF!,Inputs!$B$2*(1+Inputs!$B$4)*(1+Inputs!$B$5),Inputs!$B$2*(1+Inputs!$B$4)),IF(YEAR($A6)=2029,IF(MONTH($A6)>=Inputs!#REF!,Inputs!$B$2*(1+Inputs!$B$4)*(1+Inputs!$B$5)*(1+Inputs!$B$6),Inputs!$B$2*(1+Inputs!$B$4)*(1+Inputs!$B$5)),IF(MONTH($A6)>=Inputs!#REF!,Inputs!$B$2*(1+Inputs!$B$4)*(1+Inputs!$B$5)*(1+Inputs!$B$6)*(1+Inputs!$B$7),Inputs!$B$2*(1+Inputs!$B$4)*(1+Inputs!$B$5)*(1+Inputs!$B$6)))))))/12)*(MIN(Inputs!$B$17,Inputs!$B$18)*(1+Inputs!$B$19)+Inputs!$B$17*Inputs!$B$20),0) -> 0 | H6: =SUM(B6:G6) -> 4166.6667 | I6: =$H6-J6-K6 -> 3293.34 | J6: =_xlfn.SINGLE(_xlfn.LET(_xlpm.d, $A6, _xlpm.ys, YEAR(_xlfn.SINGLE(_xlpm.d)) - IF(MONTH(_xlfn.SINGLE(_xlpm.d)) < UK_TaxYear_Start_Month, 1, 0), _xlpm.start, DATE(_xlfn.SINGLE(_xlpm.ys), UK_TaxYear_Start_Month, 1), _xlpm.m, DATEDIF(_xlfn.SINGLE(_xlpm.start), _xlfn.SINGLE(_xlpm.d), "m") + 1, _xlpm.cum, SUMIFS($H$2:$H$54, $A$2:$A$54, ">=" & _xlfn.SINGLE(_xlpm.start), $A$2:$A$54, "<=" & _xlfn.SINGLE(_xlpm.d)), _xlpm.pa, UK_Personal_Allowance_Annual / 12 * _xlfn.SINGLE(_xlpm.m), _xlpm.br, (UK_Basic_Band_Upper_Annual - UK_Personal_Allowance_Annual) / 12 * _xlfn.SINGLE(_xlpm.m), _xlpm.hr, (UK_Higher_Band_Upper_Annual - UK_Basic_Band_Upper_Annual) / 12 * _xlfn.SINGLE(_xlpm.m), _xlpm.taxable, MAX(0, _xlfn.SINGLE(_xlpm.cum) - _xlfn.SINGLE(_xlpm.pa)), _xlpm.tax_to_date, UK_Basic_Rate * MIN(_xlpm.taxable, _xlpm.br) + UK_Higher_Rate * MIN(MAX(_xlfn.SINGLE(_xlpm.taxable) - _xlfn.SINGLE(_xlpm.br), 0), _xlpm.hr) + UK_Additional_Rate * MAX(_xlfn.SINGLE(_xlpm.taxable) - _xlfn.SINGLE(_xlpm.br) - _xlfn.SINGLE(_xlpm.hr), 0), _xlpm.prior, SUMIFS($J$2:$J$54, $A$2:$A$54, ">=" & _xlfn.SINGLE(_xlpm.start), $A$2:$A$54, "<" & _xlfn.SINGLE(_xlpm.d)), MAX(0, _xlfn.SINGLE(_xlpm.tax_to_date) - _xlfn.SINGLE(_xlpm.prior)))) -> 623.83333 | K6: =_xlfn.SINGLE(_xlfn.LET(_xlpm.g, $H6, _xlpm.pt, UK_NI_PT_Monthly, _xlpm.uel, UK_NI_UEL_Monthly, IF(_xlfn.SINGLE(_xlpm.g) <= _xlfn.SINGLE(_xlpm.pt), 0, UK_NI_Main_Rate * MIN(_xlfn.SINGLE(_xlpm.g) - _xlfn.SINGLE(_xlpm.pt), _xlfn.SINGLE(_xlpm.uel) - _xlfn.SINGLE(_xlpm.pt)) + UK_NI_Upper_Rate * MAX(_xlfn.SINGLE(_xlpm.g) - _xlfn.SINGLE(_xlpm.uel), 0)))) -> 249.49333 | L6: =IF($A6<DATE(2026,10,1),Bonus_Pct_Aug2026_to_Sep2026,IF($A6<DATE(2027,10,1),Bonus_Pct_Oct2026_to_Sep2027,IF($A6<DATE(2028,10,1),Bonus_Pct_Oct2027_to_Sep2028,IF($A6<DATE(2029,10,1),Bonus_Pct_Oct2028_to_Sep2029,Bonus_Pct_Oct2029_onwards)))) -> 0.08 | M6: Total Net in 2026 | N6: =SUM(I2:I6) -> 20162.02
A7: 46388 | B7: =(IF(YEAR($A7)=2026,Base_Annual_Salary_GBP,IF(YEAR($A7)=2027,Base_Annual_Salary_GBP*(IF(MONTH($A7)>=4,(1+Raise_Pct_Apr2027),1)*IF(MONTH($A7)>=10,(1+Raise_Pct_Nov2027),1)),IF(YEAR($A7)=2028,Base_Annual_Salary_GBP*((1+Raise_Pct_Apr2027)*(1+Raise_Pct_Nov2027))*(IF(MONTH($A7)>=4,(1+Raise_Pct_Apr2028),1)*IF(MONTH($A7)>=10,(1+Raise_Pct_Nov2028),1)),IF(YEAR($A7)=2029,Base_Annual_Salary_GBP*((1+Raise_Pct_Apr2027)*(1+Raise_Pct_Nov2027)*(1+Raise_Pct_Apr2028)*(1+Raise_Pct_Nov2028))*(IF(MONTH($A7)>=4,(1+Raise_Pct_Apr2029),1)*IF(MONTH($A7)>=10,(1+Raise_Pct_Nov2029),1)),Base_Annual_Salary_GBP*((1+Raise_Pct_Apr2027)*(1+Raise_Pct_Nov2027)*(1+Raise_Pct_Apr2028)*(1+Raise_Pct_Nov2028)*(1+Raise_Pct_Apr2029)*(1+Raise_Pct_Nov2029))*(IF(MONTH($A7)>=4,(1+Raise_Pct_Apr2030),1)*IF(MONTH($A7)>=10,(1+Raise_Pct_Nov2030),1)))))))/12 -> 4166.6667 | C7: =IF(MONTH($A7)=11,((IF(DATE(YEAR($A7),4,1)<DATE(2026,10,1),Bonus_Pct_Aug2026_to_Sep2026,IF(DATE(YEAR($A7),4,1)<DATE(2027,10,1),Bonus_Pct_Oct2026_to_Sep2027,IF(DATE(YEAR($A7),4,1)<DATE(2028,10,1),Bonus_Pct_Oct2027_to_Sep2028,IF(DATE(YEAR($A7),4,1)<DATE(2029,10,1),Bonus_Pct_Oct2028_to_Sep2029,Bonus_Pct_Oct2029_onwards)))))/2)*($B7*12) / (1 + IF(YEAR($A7)=2027,Raise_Pct_Nov2027,IF(YEAR($A7)=2028,Raise_Pct_Nov2028,IF(YEAR($A7)=2029,Raise_Pct_Nov2029,IF(YEAR($A7)=2030,Raise_Pct_Nov2030,0))))) * IF(YEAR($A7)=2026,2/6,1),IF(MONTH($A7)=5,((IF(DATE(YEAR($A7)-1,10,1)<DATE(2026,10,1),Bonus_Pct_Aug2026_to_Sep2026,IF(DATE(YEAR($A7)-1,10,1)<DATE(2027,10,1),Bonus_Pct_Oct2026_to_Sep2027,IF(DATE(YEAR($A7)-1,10,1)<DATE(2028,10,1),Bonus_Pct_Oct2027_to_Sep2028,IF(DATE(YEAR($A7)-1,10,1)<DATE(2029,10,1),Bonus_Pct_Oct2028_to_Sep2029,Bonus_Pct_Oct2029_onwards)))))/2)*($B7*12) / (1 + IF(YEAR($A7)=2027,Raise_Pct_Apr2027,IF(YEAR($A7)=2028,Raise_Pct_Apr2028,IF(YEAR($A7)=2029,Raise_Pct_Apr2029,IF(YEAR($A7)=2030,Raise_Pct_Apr2030,0))))),0)) -> 0 | D7: =IF(OR($A7=DATE(2027,9,1),$A7=EDATE(DATE(2027,9,1),12),$A7=EDATE(DATE(2027,9,1),24)),(New_Hire_Stock_Grant_USD/3)/FX_USD_per_GBP*(1+IF(YEAR($A7)=2027,Inputs!$B$56,IF(YEAR($A7)=2028,Inputs!$B$57,IF(YEAR($A7)=2029,Inputs!$B$58,0)))),0)+IF(OR($A7=DATE(2028,11,1),$A7=DATE(2029,11,1),$A7=DATE(2030,11,1)),(RSU_Grant_Nov2027_USD/3)/FX_USD_per_GBP*(1+RSU_Price_Change_Pct)^(YEAR($A7)-2028),0)+IF(OR($A7=DATE(2029,11,1),$A7=DATE(2030,11,1)),(RSU_Grant_Nov2028_USD/3)/FX_USD_per_GBP*(1+RSU_Price_Change_Pct)^(YEAR($A7)-2029),0)+IF($A7=DATE(2030,11,1),(RSU_Grant_Nov2029_USD/3)/FX_USD_per_GBP*(1+RSU_Price_Change_Pct)^(YEAR($A7)-2030),0) -> 0 | E7: =IF($A7=EDATE(DATE(2026,8,1),Inputs!$B$9),Inputs!$B$8,0) -> 0 | F7: =IF($A7=EDATE(DATE(2026,8,1),Inputs!$B$11),Inputs!$B$10,0) -> 0 | G7: =IF(Inputs!$B$16=1,((IF(YEAR($A7)=2026,Inputs!$B$2,IF(YEAR($A7)=2027,IF(MONTH($A7)>=Inputs!#REF!,Inputs!$B$2*(1+Inputs!$B$4),Inputs!$B$2),IF(YEAR($A7)=2028,IF(MONTH($A7)>=Inputs!#REF!,Inputs!$B$2*(1+Inputs!$B$4)*(1+Inputs!$B$5),Inputs!$B$2*(1+Inputs!$B$4)),IF(YEAR($A7)=2029,IF(MONTH($A7)>=Inputs!#REF!,Inputs!$B$2*(1+Inputs!$B$4)*(1+Inputs!$B$5)*(1+Inputs!$B$6),Inputs!$B$2*(1+Inputs!$B$4)*(1+Inputs!$B$5)),IF(MONTH($A7)>=Inputs!#REF!,Inputs!$B$2*(1+Inputs!$B$4)*(1+Inputs!$B$5)*(1+Inputs!$B$6)*(1+Inputs!$B$7),Inputs!$B$2*(1+Inputs!$B$4)*(1+Inputs!$B$5)*(1+Inputs!$B$6)))))))/12)*(MIN(Inputs!$B$17,Inputs!$B$18)*(1+Inputs!$B$19)+Inputs!$B$17*Inputs!$B$20),0) -> 0 | H7: =SUM(B7:G7) -> 4166.6667 | I7: =$H7-J7-K7 -> 3293.34 | J7: =_xlfn.SINGLE(_xlfn.LET(_xlpm.d, $A7, _xlpm.ys, YEAR(_xlfn.SINGLE(_xlpm.d)) - IF(MONTH(_xlfn.SINGLE(_xlpm.d)) < UK_TaxYear_Start_Month, 1, 0), _xlpm.start, DATE(_xlfn.SINGLE(_xlpm.ys), UK_TaxYear_Start_Month, 1), _xlpm.m, DATEDIF(_xlfn.SINGLE(_xlpm.start), _xlfn.SINGLE(_xlpm.d), "m") + 1, _xlpm.cum, SUMIFS($H$2:$H$54, $A$2:$A$54, ">=" & _xlfn.SINGLE(_xlpm.start), $A$2:$A$54, "<=" & _xlfn.SINGLE(_xlpm.d)), _xlpm.pa, UK_Personal_Allowance_Annual / 12 * _xlfn.SINGLE(_xlpm.m), _xlpm.br, (UK_Basic_Band_Upper_Annual - UK_Personal_Allowance_Annual) / 12 * _xlfn.SINGLE(_xlpm.m), _xlpm.hr, (UK_Higher_Band_Upper_Annual - UK_Basic_Band_Upper_Annual) / 12 * _xlfn.SINGLE(_xlpm.m), _xlpm.taxable, MAX(0, _xlfn.SINGLE(_xlpm.cum) - _xlfn.SINGLE(_xlpm.pa)), _xlpm.tax_to_date, UK_Basic_Rate * MIN(_xlpm.taxable, _xlpm.br) + UK_Higher_Rate * MIN(MAX(_xlfn.SINGLE(_xlpm.taxable) - _xlfn.SINGLE(_xlpm.br), 0), _xlpm.hr) + UK_Additional_Rate * MAX(_xlfn.SINGLE(_xlpm.taxable) - _xlfn.SINGLE(_xlpm.br) - _xlfn.SINGLE(_xlpm.hr), 0), _xlpm.prior, SUMIFS($J$2:$J$54, $A$2:$A$54, ">=" & _xlfn.SINGLE(_xlpm.start), $A$2:$A$54, "<" & _xlfn.SINGLE(_xlpm.d)), MAX(0, _xlfn.SINGLE(_xlpm.tax_to_date) - _xlfn.SINGLE(_xlpm.prior)))) -> 623.83333 | K7: =_xlfn.SINGLE(_xlfn.LET(_xlpm.g, $H7, _xlpm.pt, UK_NI_PT_Monthly, _xlpm.uel, UK_NI_UEL_Monthly, IF(_xlfn.SINGLE(_xlpm.g) <= _xlfn.SINGLE(_xlpm.pt), 0, UK_NI_Main_Rate * MIN(_xlfn.SINGLE(_xlpm.g) - _xlfn.SINGLE(_xlpm.pt), _xlfn.SINGLE(_xlpm.uel) - _xlfn.SINGLE(_xlpm.pt)) + UK_NI_Upper_Rate * MAX(_xlfn.SINGLE(_xlpm.g) - _xlfn.SINGLE(_xlpm.uel), 0)))) -> 249.49333 | L7: =IF($A7<DATE(2026,10,1),Bonus_Pct_Aug2026_to_Sep2026,IF($A7<DATE(2027,10,1),Bonus_Pct_Oct2026_to_Sep2027,IF($A7<DATE(2028,10,1),Bonus_Pct_Oct2027_to_Sep2028,IF($A7<DATE(2029,10,1),Bonus_Pct_Oct2028_to_Sep2029,Bonus_Pct_Oct2029_onwards)))) -> 0.08 | M7: Total Net in 2027 | N7: =SUM(I7:I18) -> 46820.526
A8: 46419 | B8: =(IF(YEAR($A8)=2026,Base_Annual_Salary_GBP,IF(YEAR($A8)=2027,Base_Annual_Salary_GBP*(IF(MONTH($A8)>=4,(1+Raise_Pct_Apr2027),1)*IF(MONTH($A8)>=10,(1+Raise_Pct_Nov2027),1)),IF(YEAR($A8)=2028,Base_Annual_Salary_GBP*((1+Raise_Pct_Apr2027)*(1+Raise_Pct_Nov2027))*(IF(MONTH($A8)>=4,(1+Raise_Pct_Apr2028),1)*IF(MONTH($A8)>=10,(1+Raise_Pct_Nov2028),1)),IF(YEAR($A8)=2029,Base_Annual_Salary_GBP*((1+Raise_Pct_Apr2027)*(1+Raise_Pct_Nov2027)*(1+Raise_Pct_Apr2028)*(1+Raise_Pct_Nov2028))*(IF(MONTH($A8)>=4,(1+Raise_Pct_Apr2029),1)*IF(MONTH($A8)>=10,(1+Raise_Pct_Nov2029),1)),Base_Annual_Salary_GBP*((1+Raise_Pct_Apr2027)*(1+Raise_Pct_Nov2027)*(1+Raise_Pct_Apr2028)*(1+Raise_Pct_Nov2028)*(1+Raise_Pct_Apr2029)*(1+Raise_Pct_Nov2029))*(IF(MONTH($A8)>=4,(1+Raise_Pct_Apr2030),1)*IF(MONTH($A8)>=10,(1+Raise_Pct_Nov2030),1)))))))/12 -> 4166.6667 | C8: =IF(MONTH($A8)=11,((IF(DATE(YEAR($A8),4,1)<DATE(2026,10,1),Bonus_Pct_Aug2026_to_Sep2026,IF(DATE(YEAR($A8),4,1)<DATE(2027,10,1),Bonus_Pct_Oct2026_to_Sep2027,IF(DATE(YEAR($A8),4,1)<DATE(2028,10,1),Bonus_Pct_Oct2027_to_Sep2028,IF(DATE(YEAR($A8),4,1)<DATE(2029,10,1),Bonus_Pct_Oct2028_to_Sep2029,Bonus_Pct_Oct2029_onwards)))))/2)*($B8*12) / (1 + IF(YEAR($A8)=2027,Raise_Pct_Nov2027,IF(YEAR($A8)=2028,Raise_Pct_Nov2028,IF(YEAR($A8)=2029,Raise_Pct_Nov2029,IF(YEAR($A8)=2030,Raise_Pct_Nov2030,0))))) * IF(YEAR($A8)=2026,2/6,1),IF(MONTH($A8)=5,((IF(DATE(YEAR($A8)-1,10,1)<DATE(2026,10,1),Bonus_Pct_Aug2026_to_Sep2026,IF(DATE(YEAR($A8)-1,10,1)<DATE(2027,10,1),Bonus_Pct_Oct2026_to_Sep2027,IF(DATE(YEAR($A8)-1,10,1)<DATE(2028,10,1),Bonus_Pct_Oct2027_to_Sep2028,IF(DATE(YEAR($A8)-1,10,1)<DATE(2029,10,1),Bonus_Pct_Oct2028_to_Sep2029,Bonus_Pct_Oct2029_onwards)))))/2)*($B8*12) / (1 + IF(YEAR($A8)=2027,Raise_Pct_Apr2027,IF(YEAR($A8)=2028,Raise_Pct_Apr2028,IF(YEAR($A8)=2029,Raise_Pct_Apr2029,IF(YEAR($A8)=2030,Raise_Pct_Apr2030,0))))),0)) -> 0 | D8: =IF(OR($A8=DATE(2027,9,1),$A8=EDATE(DATE(2027,9,1),12),$A8=EDATE(DATE(2027,9,1),24)),(New_Hire_Stock_Grant_USD/3)/FX_USD_per_GBP*(1+IF(YEAR($A8)=2027,Inputs!$B$56,IF(YEAR($A8)=2028,Inputs!$B$57,IF(YEAR($A8)=2029,Inputs!$B$58,0)))),0)+IF(OR($A8=DATE(2028,11,1),$A8=DATE(2029,11,1),$A8=DATE(2030,11,1)),(RSU_Grant_Nov2027_USD/3)/FX_USD_per_GBP*(1+RSU_Price_Change_Pct)^(YEAR($A8)-2028),0)+IF(OR($A8=DATE(2029,11,1),$A8=DATE(2030,11,1)),(RSU_Grant_Nov2028_USD/3)/FX_USD_per_GBP*(1+RSU_Price_Change_Pct)^(YEAR($A8)-2029),0)+IF($A8=DATE(2030,11,1),(RSU_Grant_Nov2029_USD/3)/FX_USD_per_GBP*(1+RSU_Price_Change_Pct)^(YEAR($A8)-2030),0) -> 0 | E8: =IF($A8=EDATE(DATE(2026,8,1),Inputs!$B$9),Inputs!$B$8,0) -> 0 | F8: =IF($A8=EDATE(DATE(2026,8,1),Inputs!$B$11),Inputs!$B$10,0) -> 0 | G8: =IF(Inputs!$B$16=1,((IF(YEAR($A8)=2026,Inputs!$B$2,IF(YEAR($A8)=2027,IF(MONTH($A8)>=Inputs!#REF!,Inputs!$B$2*(1+Inputs!$B$4),Inputs!$B$2),IF(YEAR($A8)=2028,IF(MONTH($A8)>=Inputs!#REF!,Inputs!$B$2*(1+Inputs!$B$4)*(1+Inputs!$B$5),Inputs!$B$2*(1+Inputs!$B$4)),IF(YEAR($A8)=2029,IF(MONTH($A8)>=Inputs!#REF!,Inputs!$B$2*(1+Inputs!$B$4)*(1+Inputs!$B$5)*(1+Inputs!$B$6),Inputs!$B$2*(1+Inputs!$B$4)*(1+Inputs!$B$5)),IF(MONTH($A8)>=Inputs!#REF!,Inputs!$B$2*(1+Inputs!$B$4)*(1+Inputs!$B$5)*(1+Inputs!$B$6)*(1+Inputs!$B$7),Inputs!$B$2*(1+Inputs!$B$4)*(1+Inputs!$B$5)*(1+Inputs!$B$6)))))))/12)*(MIN(Inputs!$B$17,Inputs!$B$18)*(1+Inputs!$B$19)+Inputs!$B$17*Inputs!$B$20),0) -> 0 | H8: =SUM(B8:G8) -> 4166.6667 | I8: =$H8-J8-K8 -> 3293.34 | J8: =_xlfn.SINGLE(_xlfn.LET(_xlpm.d, $A8, _xlpm.ys, YEAR(_xlfn.SINGLE(_xlpm.d)) - IF(MONTH(_xlfn.SINGLE(_xlpm.d)) < UK_TaxYear_Start_Month, 1, 0), _xlpm.start, DATE(_xlfn.SINGLE(_xlpm.ys), UK_TaxYear_Start_Month, 1), _xlpm.m, DATEDIF(_xlfn.SINGLE(_xlpm.start), _xlfn.SINGLE(_xlpm.d), "m") + 1, _xlpm.cum, SUMIFS($H$2:$H$54, $A$2:$A$54, ">=" & _xlfn.SINGLE(_xlpm.start), $A$2:$A$54, "<=" & _xlfn.SINGLE(_xlpm.d)), _xlpm.pa, UK_Personal_Allowance_Annual / 12 * _xlfn.SINGLE(_xlpm.m), _xlpm.br, (UK_Basic_Band_Upper_Annual - UK_Personal_Allowance_Annual) / 12 * _xlfn.SINGLE(_xlpm.m), _xlpm.hr, (UK_Higher_Band_Upper_Annual - UK_Basic_Band_Upper_Annual) / 12 * _xlfn.SINGLE(_xlpm.m), _xlpm.taxable, MAX(0, _xlfn.SINGLE(_xlpm.cum) - _xlfn.SINGLE(_xlpm.pa)), _xlpm.tax_to_date, UK_Basic_Rate * MIN(_xlpm.taxable, _xlpm.br) + UK_Higher_Rate * MIN(MAX(_xlfn.SINGLE(_xlpm.taxable) - _xlfn.SINGLE(_xlpm.br), 0), _xlpm.hr) + UK_Additional_Rate * MAX(_xlfn.SINGLE(_xlpm.taxable) - _xlfn.SINGLE(_xlpm.br) - _xlfn.SINGLE(_xlpm.hr), 0), _xlpm.prior, SUMIFS($J$2:$J$54, $A$2:$A$54, ">=" & _xlfn.SINGLE(_xlpm.start), $A$2:$A$54, "<" & _xlfn.SINGLE(_xlpm.d)), MAX(0, _xlfn.SINGLE(_xlpm.tax_to_date) - _xlfn.SINGLE(_xlpm.prior)))) -> 623.83333 | K8: =_xlfn.SINGLE(_xlfn.LET(_xlpm.g, $H8, _xlpm.pt, UK_NI_PT_Monthly, _xlpm.uel, UK_NI_UEL_Monthly, IF(_xlfn.SINGLE(_xlpm.g) <= _xlfn.SINGLE(_xlpm.pt), 0, UK_NI_Main_Rate * MIN(_xlfn.SINGLE(_xlpm.g) - _xlfn.SINGLE(_xlpm.pt), _xlfn.SINGLE(_xlpm.uel) - _xlfn.SINGLE(_xlpm.pt)) + UK_NI_Upper_Rate * MAX(_xlfn.SINGLE(_xlpm.g) - _xlfn.SINGLE(_xlpm.uel), 0)))) -> 249.49333 | L8: =IF($A8<DATE(2026,10,1),Bonus_Pct_Aug2026_to_Sep2026,IF($A8<DATE(2027,10,1),Bonus_Pct_Oct2026_to_Sep2027,IF($A8<DATE(2028,10,1),Bonus_Pct_Oct2027_to_Sep2028,IF($A8<DATE(2029,10,1),Bonus_Pct_Oct2028_to_Sep2029,Bonus_Pct_Oct2029_onwards)))) -> 0.08 | M8: Total Net in 2028 | N8: =SUM(I19:I30) -> 48020.971
A9: 46447 | B9: =(IF(YEAR($A9)=2026,Base_Annual_Salary_GBP,IF(YEAR($A9)=2027,Base_Annual_Salary_GBP*(IF(MONTH($A9)>=4,(1+Raise_Pct_Apr2027),1)*IF(MONTH($A9)>=10,(1+Raise_Pct_Nov2027),1)),IF(YEAR($A9)=2028,Base_Annual_Salary_GBP*((1+Raise_Pct_Apr2027)*(1+Raise_Pct_Nov2027))*(IF(MONTH($A9)>=4,(1+Raise_Pct_Apr2028),1)*IF(MONTH($A9)>=10,(1+Raise_Pct_Nov2028),1)),IF(YEAR($A9)=2029,Base_Annual_Salary_GBP*((1+Raise_Pct_Apr2027)*(1+Raise_Pct_Nov2027)*(1+Raise_Pct_Apr2028)*(1+Raise_Pct_Nov2028))*(IF(MONTH($A9)>=4,(1+Raise_Pct_Apr2029),1)*IF(MONTH($A9)>=10,(1+Raise_Pct_Nov2029),1)),Base_Annual_Salary_GBP*((1+Raise_Pct_Apr2027)*(1+Raise_Pct_Nov2027)*(1+Raise_Pct_Apr2028)*(1+Raise_Pct_Nov2028)*(1+Raise_Pct_Apr2029)*(1+Raise_Pct_Nov2029))*(IF(MONTH($A9)>=4,(1+Raise_Pct_Apr2030),1)*IF(MONTH($A9)>=10,(1+Raise_Pct_Nov2030),1)))))))/12 -> 4166.6667 | C9: =IF(MONTH($A9)=11,((IF(DATE(YEAR($A9),4,1)<DATE(2026,10,1),Bonus_Pct_Aug2026_to_Sep2026,IF(DATE(YEAR($A9),4,1)<DATE(2027,10,1),Bonus_Pct_Oct2026_to_Sep2027,IF(DATE(YEAR($A9),4,1)<DATE(2028,10,1),Bonus_Pct_Oct2027_to_Sep2028,IF(DATE(YEAR($A9),4,1)<DATE(2029,10,1),Bonus_Pct_Oct2028_to_Sep2029,Bonus_Pct_Oct2029_onwards)))))/2)*($B9*12) / (1 + IF(YEAR($A9)=2027,Raise_Pct_Nov2027,IF(YEAR($A9)=2028,Raise_Pct_Nov2028,IF(YEAR($A9)=2029,Raise_Pct_Nov2029,IF(YEAR($A9)=2030,Raise_Pct_Nov2030,0))))) * IF(YEAR($A9)=2026,2/6,1),IF(MONTH($A9)=5,((IF(DATE(YEAR($A9)-1,10,1)<DATE(2026,10,1),Bonus_Pct_Aug2026_to_Sep2026,IF(DATE(YEAR($A9)-1,10,1)<DATE(2027,10,1),Bonus_Pct_Oct2026_to_Sep2027,IF(DATE(YEAR($A9)-1,10,1)<DATE(2028,10,1),Bonus_Pct_Oct2027_to_Sep2028,IF(DATE(YEAR($A9)-1,10,1)<DATE(2029,10,1),Bonus_Pct_Oct2028_to_Sep2029,Bonus_Pct_Oct2029_onwards)))))/2)*($B9*12) / (1 + IF(YEAR($A9)=2027,Raise_Pct_Apr2027,IF(YEAR($A9)=2028,Raise_Pct_Apr2028,IF(YEAR($A9)=2029,Raise_Pct_Apr2029,IF(YEAR($A9)=2030,Raise_Pct_Apr2030,0))))),0)) -> 0 | D9: =IF(OR($A9=DATE(2027,9,1),$A9=EDATE(DATE(2027,9,1),12),$A9=EDATE(DATE(2027,9,1),24)),(New_Hire_Stock_Grant_USD/3)/FX_USD_per_GBP*(1+IF(YEAR($A9)=2027,Inputs!$B$56,IF(YEAR($A9)=2028,Inputs!$B$57,IF(YEAR($A9)=2029,Inputs!$B$58,0)))),0)+IF(OR($A9=DATE(2028,11,1),$A9=DATE(2029,11,1),$A9=DATE(2030,11,1)),(RSU_Grant_Nov2027_USD/3)/FX_USD_per_GBP*(1+RSU_Price_Change_Pct)^(YEAR($A9)-2028),0)+IF(OR($A9=DATE(2029,11,1),$A9=DATE(2030,11,1)),(RSU_Grant_Nov2028_USD/3)/FX_USD_per_GBP*(1+RSU_Price_Change_Pct)^(YEAR($A9)-2029),0)+IF($A9=DATE(2030,11,1),(RSU_Grant_Nov2029_USD/3)/FX_USD_per_GBP*(1+RSU_Price_Change_Pct)^(YEAR($A9)-2030),0) -> 0 | E9: =IF($A9=EDATE(DATE(2026,8,1),Inputs!$B$9),Inputs!$B$8,0) -> 0 | F9: =IF($A9=EDATE(DATE(2026,8,1),Inputs!$B$11),Inputs!$B$10,0) -> 0 | G9: =IF(Inputs!$B$16=1,((IF(YEAR($A9)=2026,Inputs!$B$2,IF(YEAR($A9)=2027,IF(MONTH($A9)>=Inputs!#REF!,Inputs!$B$2*(1+Inputs!$B$4),Inputs!$B$2),IF(YEAR($A9)=2028,IF(MONTH($A9)>=Inputs!#REF!,Inputs!$B$2*(1+Inputs!$B$4)*(1+Inputs!$B$5),Inputs!$B$2*(1+Inputs!$B$4)),IF(YEAR($A9)=2029,IF(MONTH($A9)>=Inputs!#REF!,Inputs!$B$2*(1+Inputs!$B$4)*(1+Inputs!$B$5)*(1+Inputs!$B$6),Inputs!$B$2*(1+Inputs!$B$4)*(1+Inputs!$B$5)),IF(MONTH($A9)>=Inputs!#REF!,Inputs!$B$2*(1+Inputs!$B$4)*(1+Inputs!$B$5)*(1+Inputs!$B$6)*(1+Inputs!$B$7),Inputs!$B$2*(1+Inputs!$B$4)*(1+Inputs!$B$5)*(1+Inputs!$B$6)))))))/12)*(MIN(Inputs!$B$17,Inputs!$B$18)*(1+Inputs!$B$19)+Inputs!$B$17*Inputs!$B$20),0) -> 0 | H9: =SUM(B9:G9) -> 4166.6667 | I9: =$H9-J9-K9 -> 3293.34 | J9: =_xlfn.SINGLE(_xlfn.LET(_xlpm.d, $A9, _xlpm.ys, YEAR(_xlfn.SINGLE(_xlpm.d)) - IF(MONTH(_xlfn.SINGLE(_xlpm.d)) < UK_TaxYear_Start_Month, 1, 0), _xlpm.start, DATE(_xlfn.SINGLE(_xlpm.ys), UK_TaxYear_Start_Month, 1), _xlpm.m, DATEDIF(_xlfn.SINGLE(_xlpm.start), _xlfn.SINGLE(_xlpm.d), "m") + 1, _xlpm.cum, SUMIFS($H$2:$H$54, $A$2:$A$54, ">=" & _xlfn.SINGLE(_xlpm.start), $A$2:$A$54, "<=" & _xlfn.SINGLE(_xlpm.d)), _xlpm.pa, UK_Personal_Allowance_Annual / 12 * _xlfn.SINGLE(_xlpm.m), _xlpm.br, (UK_Basic_Band_Upper_Annual - UK_Personal_Allowance_Annual) / 12 * _xlfn.SINGLE(_xlpm.m), _xlpm.hr, (UK_Higher_Band_Upper_Annual - UK_Basic_Band_Upper_Annual) / 12 * _xlfn.SINGLE(_xlpm.m), _xlpm.taxable, MAX(0, _xlfn.SINGLE(_xlpm.cum) - _xlfn.SINGLE(_xlpm.pa)), _xlpm.tax_to_date, UK_Basic_Rate * MIN(_xlpm.taxable, _xlpm.br) + UK_Higher_Rate * MIN(MAX(_xlfn.SINGLE(_xlpm.taxable) - _xlfn.SINGLE(_xlpm.br), 0), _xlpm.hr) + UK_Additional_Rate * MAX(_xlfn.SINGLE(_xlpm.taxable) - _xlfn.SINGLE(_xlpm.br) - _xlfn.SINGLE(_xlpm.hr), 0), _xlpm.prior, SUMIFS($J$2:$J$54, $A$2:$A$54, ">=" & _xlfn.SINGLE(_xlpm.start), $A$2:$A$54, "<" & _xlfn.SINGLE(_xlpm.d)), MAX(0, _xlfn.SINGLE(_xlpm.tax_to_date) - _xlfn.SINGLE(_xlpm.prior)))) -> 623.83333 | K9: =_xlfn.SINGLE(_xlfn.LET(_xlpm.g, $H9, _xlpm.pt, UK_NI_PT_Monthly, _xlpm.uel, UK_NI_UEL_Monthly, IF(_xlfn.SINGLE(_xlpm.g) <= _xlfn.SINGLE(_xlpm.pt), 0, UK_NI_Main_Rate * MIN(_xlfn.SINGLE(_xlpm.g) - _xlfn.SINGLE(_xlpm.pt), _xlfn.SINGLE(_xlpm.uel) - _xlfn.SINGLE(_xlpm.pt)) + UK_NI_Upper_Rate * MAX(_xlfn.SINGLE(_xlpm.g) - _xlfn.SINGLE(_xlpm.uel), 0)))) -> 249.49333 | L9: =IF($A9<DATE(2026,10,1),Bonus_Pct_Aug2026_to_Sep2026,IF($A9<DATE(2027,10,1),Bonus_Pct_Oct2026_to_Sep2027,IF($A9<DATE(2028,10,1),Bonus_Pct_Oct2027_to_Sep2028,IF($A9<DATE(2029,10,1),Bonus_Pct_Oct2028_to_Sep2029,Bonus_Pct_Oct2029_onwards)))) -> 0.08 | M9: Total Net in 2029 | N9: =SUM(I31:I42) -> 50441.235
A10: 46478 | B10: =(IF(YEAR($A10)=2026,Base_Annual_Salary_GBP,IF(YEAR($A10)=2027,Base_Annual_Salary_GBP*(IF(MONTH($A10)>=4,(1+Raise_Pct_Apr2027),1)*IF(MONTH($A10)>=10,(1+Raise_Pct_Nov2027),1)),IF(YEAR($A10)=2028,Base_Annual_Salary_GBP*((1+Raise_Pct_Apr2027)*(1+Raise_Pct_Nov2027))*(IF(MONTH($A10)>=4,(1+Raise_Pct_Apr2028),1)*IF(MONTH($A10)>=10,(1+Raise_Pct_Nov2028),1)),IF(YEAR($A10)=2029,Base_Annual_Salary_GBP*((1+Raise_Pct_Apr2027)*(1+Raise_Pct_Nov2027)*(1+Raise_Pct_Apr2028)*(1+Raise_Pct_Nov2028))*(IF(MONTH($A10)>=4,(1+Raise_Pct_Apr2029),1)*IF(MONTH($A10)>=10,(1+Raise_Pct_Nov2029),1)),Base_Annual_Salary_GBP*((1+Raise_Pct_Apr2027)*(1+Raise_Pct_Nov2027)*(1+Raise_Pct_Apr2028)*(1+Raise_Pct_Nov2028)*(1+Raise_Pct_Apr2029)*(1+Raise_Pct_Nov2029))*(IF(MONTH($A10)>=4,(1+Raise_Pct_Apr2030),1)*IF(MONTH($A10)>=10,(1+Raise_Pct_Nov2030),1)))))))/12 -> 4291.6667 | C10: =IF(MONTH($A10)=11,((IF(DATE(YEAR($A10),4,1)<DATE(2026,10,1),Bonus_Pct_Aug2026_to_Sep2026,IF(DATE(YEAR($A10),4,1)<DATE(2027,10,1),Bonus_Pct_Oct2026_to_Sep2027,IF(DATE(YEAR($A10),4,1)<DATE(2028,10,1),Bonus_Pct_Oct2027_to_Sep2028,IF(DATE(YEAR($A10),4,1)<DATE(2029,10,1),Bonus_Pct_Oct2028_to_Sep2029,Bonus_Pct_Oct2029_onwards)))))/2)*($B10*12) / (1 + IF(YEAR($A10)=2027,Raise_Pct_Nov2027,IF(YEAR($A10)=2028,Raise_Pct_Nov2028,IF(YEAR($A10)=2029,Raise_Pct_Nov2029,IF(YEAR($A10)=2030,Raise_Pct_Nov2030,0))))) * IF(YEAR($A10)=2026,2/6,1),IF(MONTH($A10)=5,((IF(DATE(YEAR($A10)-1,10,1)<DATE(2026,10,1),Bonus_Pct_Aug2026_to_Sep2026,IF(DATE(YEAR($A10)-1,10,1)<DATE(2027,10,1),Bonus_Pct_Oct2026_to_Sep2027,IF(DATE(YEAR($A10)-1,10,1)<DATE(2028,10,1),Bonus_Pct_Oct2027_to_Sep2028,IF(DATE(YEAR($A10)-1,10,1)<DATE(2029,10,1),Bonus_Pct_Oct2028_to_Sep2029,Bonus_Pct_Oct2029_onwards)))))/2)*($B10*12) / (1 + IF(YEAR($A10)=2027,Raise_Pct_Apr2027,IF(YEAR($A10)=2028,Raise_Pct_Apr2028,IF(YEAR($A10)=2029,Raise_Pct_Apr2029,IF(YEAR($A10)=2030,Raise_Pct_Apr2030,0))))),0)) -> 0 | D10: =IF(OR($A10=DATE(2027,9,1),$A10=EDATE(DATE(2027,9,1),12),$A10=EDATE(DATE(2027,9,1),24)),(New_Hire_Stock_Grant_USD/3)/FX_USD_per_GBP*(1+IF(YEAR($A10)=2027,Inputs!$B$56,IF(YEAR($A10)=2028,Inputs!$B$57,IF(YEAR($A10)=2029,Inputs!$B$58,0)))),0)+IF(OR($A10=DATE(2028,11,1),$A10=DATE(2029,11,1),$A10=DATE(2030,11,1)),(RSU_Grant_Nov2027_USD/3)/FX_USD_per_GBP*(1+RSU_Price_Change_Pct)^(YEAR($A10)-2028),0)+IF(OR($A10=DATE(2029,11,1),$A10=DATE(2030,11,1)),(RSU_Grant_Nov2028_USD/3)/FX_USD_per_GBP*(1+RSU_Price_Change_Pct)^(YEAR($A10)-2029),0)+IF($A10=DATE(2030,11,1),(RSU_Grant_Nov2029_USD/3)/FX_USD_per_GBP*(1+RSU_Price_Change_Pct)^(YEAR($A10)-2030),0) -> 0 | E10: =IF($A10=EDATE(DATE(2026,8,1),Inputs!$B$9),Inputs!$B$8,0) -> 0 | F10: =IF($A10=EDATE(DATE(2026,8,1),Inputs!$B$11),Inputs!$B$10,0) -> 0 | G10: =IF(Inputs!$B$16=1,((IF(YEAR($A10)=2026,Inputs!$B$2,IF(YEAR($A10)=2027,IF(MONTH($A10)>=Inputs!#REF!,Inputs!$B$2*(1+Inputs!$B$4),Inputs!$B$2),IF(YEAR($A10)=2028,IF(MONTH($A10)>=Inputs!#REF!,Inputs!$B$2*(1+Inputs!$B$4)*(1+Inputs!$B$5),Inputs!$B$2*(1+Inputs!$B$4)),IF(YEAR($A10)=2029,IF(MONTH($A10)>=Inputs!#REF!,Inputs!$B$2*(1+Inputs!$B$4)*(1+Inputs!$B$5)*(1+Inputs!$B$6),Inputs!$B$2*(1+Inputs!$B$4)*(1+Inputs!$B$5)),IF(MONTH($A10)>=Inputs!#REF!,Inputs!$B$2*(1+Inputs!$B$4)*(1+Inputs!$B$5)*(1+Inputs!$B$6)*(1+Inputs!$B$7),Inputs!$B$2*(1+Inputs!$B$4)*(1+Inputs!$B$5)*(1+Inputs!$B$6)))))))/12)*(MIN(Inputs!$B$17,Inputs!$B$18)*(1+Inputs!$B$19)+Inputs!$B$17*Inputs!$B$20),0) -> 0 | H10: =SUM(B10:G10) -> 4291.6667 | I10: =$H10-J10-K10 -> 3369 | J10: =_xlfn.SINGLE(_xlfn.LET(_xlpm.d, $A10, _xlpm.ys, YEAR(_xlfn.SINGLE(_xlpm.d)) - IF(MONTH(_xlfn.SINGLE(_xlpm.d)) < UK_TaxYear_Start_Month, 1, 0), _xlpm.start, DATE(_xlfn.SINGLE(_xlpm.ys), UK_TaxYear_Start_Month, 1), _xlpm.m, DATEDIF(_xlfn.SINGLE(_xlpm.start), _xlfn.SINGLE(_xlpm.d), "m") + 1, _xlpm.cum, SUMIFS($H$2:$H$54, $A$2:$A$54, ">=" & _xlfn.SINGLE(_xlpm.start), $A$2:$A$54, "<=" & _xlfn.SINGLE(_xlpm.d)), _xlpm.pa, UK_Personal_Allowance_Annual / 12 * _xlfn.SINGLE(_xlpm.m), _xlpm.br, (UK_Basic_Band_Upper_Annual - UK_Personal_Allowance_Annual) / 12 * _xlfn.SINGLE(_xlpm.m), _xlpm.hr, (UK_Higher_Band_Upper_Annual - UK_Basic_Band_Upper_Annual) / 12 * _xlfn.SINGLE(_xlpm.m), _xlpm.taxable, MAX(0, _xlfn.SINGLE(_xlpm.cum) - _xlfn.SINGLE(_xlpm.pa)), _xlpm.tax_to_date, UK_Basic_Rate * MIN(_xlpm.taxable, _xlpm.br) + UK_Higher_Rate * MIN(MAX(_xlfn.SINGLE(_xlpm.taxable) - _xlfn.SINGLE(_xlpm.br), 0), _xlpm.hr) + UK_Additional_Rate * MAX(_xlfn.SINGLE(_xlpm.taxable) - _xlfn.SINGLE(_xlpm.br) - _xlfn.SINGLE(_xlpm.hr), 0), _xlpm.prior, SUMIFS($J$2:$J$54, $A$2:$A$54, ">=" & _xlfn.SINGLE(_xlpm.start), $A$2:$A$54, "<" & _xlfn.SINGLE(_xlpm.d)), MAX(0, _xlfn.SINGLE(_xlpm.tax_to_date) - _xlfn.SINGLE(_xlpm.prior)))) -> 669.33333 | K10: =_xlfn.SINGLE(_xlfn.LET(_xlpm.g, $H10, _xlpm.pt, UK_NI_PT_Monthly, _xlpm.uel, UK_NI_UEL_Monthly, IF(_xlfn.SINGLE(_xlpm.g) <= _xlfn.SINGLE(_xlpm.pt), 0, UK_NI_Main_Rate * MIN(_xlfn.SINGLE(_xlpm.g) - _xlfn.SINGLE(_xlpm.pt), _xlfn.SINGLE(_xlpm.uel) - _xlfn.SINGLE(_xlpm.pt)) + UK_NI_Upper_Rate * MAX(_xlfn.SINGLE(_xlpm.g) - _xlfn.SINGLE(_xlpm.uel), 0)))) -> 253.33333 | L10: =IF($A10<DATE(2026,10,1),Bonus_Pct_Aug2026_to_Sep2026,IF($A10<DATE(2027,10,1),Bonus_Pct_Oct2026_to_Sep2027,IF($A10<DATE(2028,10,1),Bonus_Pct_Oct2027_to_Sep2028,IF($A10<DATE(2029,10,1),Bonus_Pct_Oct2028_to_Sep2029,Bonus_Pct_Oct2029_onwards)))) -> 0.08 | M10: Total Net in 2030 | N10: =SUM(I43:I54) -> 47245.085
A11: 46508 | B11: =(IF(YEAR($A11)=2026,Base_Annual_Salary_GBP,IF(YEAR($A11)=2027,Base_Annual_Salary_GBP*(IF(MONTH($A11)>=4,(1+Raise_Pct_Apr2027),1)*IF(MONTH($A11)>=10,(1+Raise_Pct_Nov2027),1)),IF(YEAR($A11)=2028,Base_Annual_Salary_GBP*((1+Raise_Pct_Apr2027)*(1+Raise_Pct_Nov2027))*(IF(MONTH($A11)>=4,(1+Raise_Pct_Apr2028),1)*IF(MONTH($A11)>=10,(1+Raise_Pct_Nov2028),1)),IF(YEAR($A11)=2029,Base_Annual_Salary_GBP*((1+Raise_Pct_Apr2027)*(1+Raise_Pct_Nov2027)*(1+Raise_Pct_Apr2028)*(1+Raise_Pct_Nov2028))*(IF(MONTH($A11)>=4,(1+Raise_Pct_Apr2029),1)*IF(MONTH($A11)>=10,(1+Raise_Pct_Nov2029),1)),Base_Annual_Salary_GBP*((1+Raise_Pct_Apr2027)*(1+Raise_Pct_Nov2027)*(1+Raise_Pct_Apr2028)*(1+Raise_Pct_Nov2028)*(1+Raise_Pct_Apr2029)*(1+Raise_Pct_Nov2029))*(IF(MONTH($A11)>=4,(1+Raise_Pct_Apr2030),1)*IF(MONTH($A11)>=10,(1+Raise_Pct_Nov2030),1)))))))/12 -> 4291.6667 | C11: =IF(MONTH($A11)=11,((IF(DATE(YEAR($A11),4,1)<DATE(2026,10,1),Bonus_Pct_Aug2026_to_Sep2026,IF(DATE(YEAR($A11),4,1)<DATE(2027,10,1),Bonus_Pct_Oct2026_to_Sep2027,IF(DATE(YEAR($A11),4,1)<DATE(2028,10,1),Bonus_Pct_Oct2027_to_Sep2028,IF(DATE(YEAR($A11),4,1)<DATE(2029,10,1),Bonus_Pct_Oct2028_to_Sep2029,Bonus_Pct_Oct2029_onwards)))))/2)*($B11*12) / (1 + IF(YEAR($A11)=2027,Raise_Pct_Nov2027,IF(YEAR($A11)=2028,Raise_Pct_Nov2028,IF(YEAR($A11)=2029,Raise_Pct_Nov2029,IF(YEAR($A11)=2030,Raise_Pct_Nov2030,0))))) * IF(YEAR($A11)=2026,2/6,1),IF(MONTH($A11)=5,((IF(DATE(YEAR($A11)-1,10,1)<DATE(2026,10,1),Bonus_Pct_Aug2026_to_Sep2026,IF(DATE(YEAR($A11)-1,10,1)<DATE(2027,10,1),Bonus_Pct_Oct2026_to_Sep2027,IF(DATE(YEAR($A11)-1,10,1)<DATE(2028,10,1),Bonus_Pct_Oct2027_to_Sep2028,IF(DATE(YEAR($A11)-1,10,1)<DATE(2029,10,1),Bonus_Pct_Oct2028_to_Sep2029,Bonus_Pct_Oct2029_onwards)))))/2)*($B11*12) / (1 + IF(YEAR($A11)=2027,Raise_Pct_Apr2027,IF(YEAR($A11)=2028,Raise_Pct_Apr2028,IF(YEAR($A11)=2029,Raise_Pct_Apr2029,IF(YEAR($A11)=2030,Raise_Pct_Apr2030,0))))),0)) -> 2000 | D11: =IF(OR($A11=DATE(2027,9,1),$A11=EDATE(DATE(2027,9,1),12),$A11=EDATE(DATE(2027,9,1),24)),(New_Hire_Stock_Grant_USD/3)/FX_USD_per_GBP*(1+IF(YEAR($A11)=2027,Inputs!$B$56,IF(YEAR($A11)=2028,Inputs!$B$57,IF(YEAR($A11)=2029,Inputs!$B$58,0)))),0)+IF(OR($A11=DATE(2028,11,1),$A11=DATE(2029,11,1),$A11=DATE(2030,11,1)),(RSU_Grant_Nov2027_USD/3)/FX_USD_per_GBP*(1+RSU_Price_Change_Pct)^(YEAR($A11)-2028),0)+IF(OR($A11=DATE(2029,11,1),$A11=DATE(2030,11,1)),(RSU_Grant_Nov2028_USD/3)/FX_USD_per_GBP*(1+RSU_Price_Change_Pct)^(YEAR($A11)-2029),0)+IF($A11=DATE(2030,11,1),(RSU_Grant_Nov2029_USD/3)/FX_USD_per_GBP*(1+RSU_Price_Change_Pct)^(YEAR($A11)-2030),0) -> 0 | E11: =IF($A11=EDATE(DATE(2026,8,1),Inputs!$B$9),Inputs!$B$8,0) -> 0 | F11: =IF($A11=EDATE(DATE(2026,8,1),Inputs!$B$11),Inputs!$B$10,0) -> 0 | G11: =IF(Inputs!$B$16=1,((IF(YEAR($A11)=2026,Inputs!$B$2,IF(YEAR($A11)=2027,IF(MONTH($A11)>=Inputs!#REF!,Inputs!$B$2*(1+Inputs!$B$4),Inputs!$B$2),IF(YEAR($A11)=2028,IF(MONTH($A11)>=Inputs!#REF!,Inputs!$B$2*(1+Inputs!$B$4)*(1+Inputs!$B$5),Inputs!$B$2*(1+Inputs!$B$4)),IF(YEAR($A11)=2029,IF(MONTH($A11)>=Inputs!#REF!,Inputs!$B$2*(1+Inputs!$B$4)*(1+Inputs!$B$5)*(1+Inputs!$B$6),Inputs!$B$2*(1+Inputs!$B$4)*(1+Inputs!$B$5)),IF(MONTH($A11)>=Inputs!#REF!,Inputs!$B$2*(1+Inputs!$B$4)*(1+Inputs!$B$5)*(1+Inputs!$B$6)*(1+Inputs!$B$7),Inputs!$B$2*(1+Inputs!$B$4)*(1+Inputs!$B$5)*(1+Inputs!$B$6)))))))/12)*(MIN(Inputs!$B$17,Inputs!$B$18)*(1+Inputs!$B$19)+Inputs!$B$17*Inputs!$B$20),0) -> 0 | H11: =SUM(B11:G11) -> 6291.6667 | I11: =$H11-J11-K11 -> 4529 | J11: =_xlfn.SINGLE(_xlfn.LET(_xlpm.d, $A11, _xlpm.ys, YEAR(_xlfn.SINGLE(_xlpm.d)) - IF(MONTH(_xlfn.SINGLE(_xlpm.d)) < UK_TaxYear_Start_Month, 1, 0), _xlpm.start, DATE(_xlfn.SINGLE(_xlpm.ys), UK_TaxYear_Start_Month, 1), _xlpm.m, DATEDIF(_xlfn.SINGLE(_xlpm.start), _xlfn.SINGLE(_xlpm.d), "m") + 1, _xlpm.cum, SUMIFS($H$2:$H$54, $A$2:$A$54, ">=" & _xlfn.SINGLE(_xlpm.start), $A$2:$A$54, "<=" & _xlfn.SINGLE(_xlpm.d)), _xlpm.pa, UK_Personal_Allowance_Annual / 12 * _xlfn.SINGLE(_xlpm.m), _xlpm.br, (UK_Basic_Band_Upper_Annual - UK_Personal_Allowance_Annual) / 12 * _xlfn.SINGLE(_xlpm.m), _xlpm.hr, (UK_Higher_Band_Upper_Annual - UK_Basic_Band_Upper_Annual) / 12 * _xlfn.SINGLE(_xlpm.m), _xlpm.taxable, MAX(0, _xlfn.SINGLE(_xlpm.cum) - _xlfn.SINGLE(_xlpm.pa)), _xlpm.tax_to_date, UK_Basic_Rate * MIN(_xlpm.taxable, _xlpm.br) + UK_Higher_Rate * MIN(MAX(_xlfn.SINGLE(_xlpm.taxable) - _xlfn.SINGLE(_xlpm.br), 0), _xlpm.hr) + UK_Additional_Rate * MAX(_xlfn.SINGLE(_xlpm.taxable) - _xlfn.SINGLE(_xlpm.br) - _xlfn.SINGLE(_xlpm.hr), 0), _xlpm.prior, SUMIFS($J$2:$J$54, $A$2:$A$54, ">=" & _xlfn.SINGLE(_xlpm.start), $A$2:$A$54, "<" & _xlfn.SINGLE(_xlpm.d)), MAX(0, _xlfn.SINGLE(_xlpm.tax_to_date) - _xlfn.SINGLE(_xlpm.prior)))) -> 1469.3333 | K11: =_xlfn.SINGLE(_xlfn.LET(_xlpm.g, $H11, _xlpm.pt, UK_NI_PT_Monthly, _xlpm.uel, UK_NI_UEL_Monthly, IF(_xlfn.SINGLE(_xlpm.g) <= _xlfn.SINGLE(_xlpm.pt), 0, UK_NI_Main_Rate * MIN(_xlfn.SINGLE(_xlpm.g) - _xlfn.SINGLE(_xlpm.pt), _xlfn.SINGLE(_xlpm.uel) - _xlfn.SINGLE(_xlpm.pt)) + UK_NI_Upper_Rate * MAX(_xlfn.SINGLE(_xlpm.g) - _xlfn.SINGLE(_xlpm.uel), 0)))) -> 293.33333 | L11: =IF($A11<DATE(2026,10,1),Bonus_Pct_Aug2026_to_Sep2026,IF($A11<DATE(2027,10,1),Bonus_Pct_Oct2026_to_Sep2027,IF($A11<DATE(2028,10,1),Bonus_Pct_Oct2027_to_Sep2028,IF($A11<DATE(2029,10,1),Bonus_Pct_Oct2028_to_Sep2029,Bonus_Pct_Oct2029_onwards)))) -> 0.08
